<sdf version='1.6'>
  <model name='spirit'>
    <link name='body'>
      <pose frame=''>0 0 0 0 -0 0</pose>
      <inertial>
        <pose frame=''>0 0 0 0 -0 0</pose>
        <mass>7.388</mass>
        <inertia>
          <ixx>0.0642435</ixx>
          <ixy>0</ixy>
          <ixz>0</ixz>
          <iyy>0.128487</iyy>
          <iyz>0</iyz>
          <izz>0.128487</izz>
        </inertia>
      </inertial>
      <collision name='body_collision'>
        <pose frame=''>0 0 0 0 -0 0</pose>
        <geometry>
          <box>
            <size>0.335 0.24 0.104</size>
          </box>
        </geometry>
        <surface>
          <contact>
            <ode/>
          </contact>
          <friction>
            <ode/>
          </friction>
        </surface>
      </collision>
      <visual name='body_visual'>
        <pose frame=''>0 0 0 0 -0 0</pose>
        <geometry>
          <box>
            <size>0.335 0.24 0.104</size>
          </box>
        </geometry>
        <material>
          <script>
            <name>Gazebo/Black</name>
            <uri>file://media/materials/scripts/gazebo.material</uri>
          </script>
        </material>
      </visual>
      <gravity>1</gravity>
      <velocity_decay/>
    </link>
    <link name='hip2'>
      <pose frame=''>0.2263 -0.07 0 0 -0 0</pose>
      <inertial>
        <pose frame=''>0 -0.028 0 1.5708 -0 0</pose>
        <mass>0.575</mass>
        <inertia>
          <ixx>0.00074151</ixx>
          <ixy>0</ixy>
          <ixz>0</ixz>
          <iyy>0.00074151</iyy>
          <iyz>0</iyz>
          <izz>0.000869688</izz>
        </inertia>
      </inertial>
      <collision name='hip2_collision'>
        <pose frame=''>0 -0.028 0 1.5708 -0 0</pose>
        <geometry>
          <cylinder>
            <length>0.08</length>
            <radius>0.055</radius>
          </cylinder>
        </geometry>
        <surface>
          <contact>
            <ode/>
          </contact>
          <friction>
            <ode/>
          </friction>
        </surface>
      </collision>
      <visual name='hip2_visual'>
        <pose frame=''>0 -0.028 0 1.5708 -0 0</pose>
        <geometry>
          <cylinder>
            <length>0.08</length>
            <radius>0.055</radius>
          </cylinder>
        </geometry>
        <material>
          <script>
            <name>Gazebo/Grey</name>
            <uri>file://media/materials/scripts/gazebo.material</uri>
          </script>
        </material>
      </visual>
      <gravity>1</gravity>
      <velocity_decay/>
    </link>
    <joint name='10' type='revolute'>
      <child>hip2</child>
      <parent>body</parent>
      <axis>
        <xyz>1 0 0</xyz>
        <limit>
          <lower>-0.707</lower>
          <upper>0.707</upper>
          <effort>21</effort>
          <velocity>37.7</velocity>
        </limit>
        <dynamics>
          <damping>0</damping>
          <friction>0</friction>
          <spring_reference>0</spring_reference>
          <spring_stiffness>0</spring_stiffness>
        </dynamics>
        <use_parent_model_frame>0</use_parent_model_frame>
      </axis>
    </joint>
    <link name='upper2'>
      <pose frame=''>0.2263 -0.17098 0 0 -0 0</pose>
      <inertial>
        <pose frame=''>-0.103 0.022 0 0 -0 0</pose>
        <mass>0.792</mass>
        <inertia>
          <ixx>0.000231594</ixx>
          <ixy>0</ixy>
          <ixz>0</ixz>
          <iyy>0.00300043</iyy>
          <iyz>0</iyz>
          <izz>0.00283272</izz>
        </inertia>
      </inertial>
      <collision name='upper2_collision'>
        <pose frame=''>-0.103 0.022 0 0 -0 0</pose>
        <geometry>
          <box>
            <size>0.206 0.022 0.055</size>
          </box>
        </geometry>
        <surface>
          <contact>
            <ode/>
          </contact>
          <friction>
            <ode/>
          </friction>
        </surface>
      </collision>
      <visual name='upper2_visual'>
        <pose frame=''>-0.103 0.022 0 0 -0 0</pose>
        <geometry>
          <box>
            <size>0.206 0.022 0.055</size>
          </box>
        </geometry>
        <material>
          <script>
            <name>Gazebo/DarkGrey</name>
            <uri>file://media/materials/scripts/gazebo.material</uri>
          </script>
        </material>
      </visual>
      <gravity>1</gravity>
      <velocity_decay/>
      <self_collide>0</self_collide>
    </link>
    <joint name='4' type='revolute'>
      <child>upper2</child>
      <parent>hip2</parent>
      <axis>
        <xyz>0 -1 0</xyz>
        <limit>
          <lower>-1.57</lower>
          <upper>3.14</upper>
          <effort>21</effort>
          <velocity>37.7</velocity>
        </limit>
        <dynamics>
          <damping>0</damping>
          <friction>0</friction>
          <spring_reference>0</spring_reference>
          <spring_stiffness>0</spring_stiffness>
        </dynamics>
        <use_parent_model_frame>0</use_parent_model_frame>
      </axis>
    </joint>
    <link name='lower2'>
      <pose frame=''>0.0203 -0.17098 0 0 -0 0</pose>
      <inertial>
        <pose frame=''>0.103 0 0 0 -0 0</pose>
        <mass>0.075</mass>
        <inertia>
          <ixx>2.19313e-05</ixx>
          <ixy>0</ixy>
          <ixz>0</ixz>
          <iyy>0.000284131</iyy>
          <iyz>0</iyz>
          <izz>0.00026825</izz>
        </inertia>
      </inertial>
      <collision name='lower2_collision'>
        <pose frame=''>0.103 0 0 3.14159 1.57079 3.14159</pose>
        <geometry>
          <cylinder>
            <length>0.206</length>
            <radius>0.013</radius>
          </cylinder>
        </geometry>
        <surface>
          <contact>
            <ode/>
          </contact>
          <friction>
            <ode/>
          </friction>
        </surface>
      </collision>
      <visual name='lower2_visual'>
        <pose frame=''>0.103 0 0 3.14159 1.57079 3.14159</pose>
        <geometry>
          <cylinder>
            <length>0.206</length>
            <radius>0.013</radius>
          </cylinder>
        </geometry>
        <material>
          <script>
            <name>Gazebo/Grey</name>
            <uri>file://media/materials/scripts/gazebo.material</uri>
          </script>
        </material>
      </visual>
      <gravity>1</gravity>
      <velocity_decay/>
    </link>
    <joint name='5' type='revolute'>
      <child>lower2</child>
      <parent>upper2</parent>
      <axis>
        <xyz>0 1 0</xyz>
        <limit>
          <lower>-6.28</lower>
          <upper>6.28</upper>
          <effort>32</effort>
          <velocity>25.1</velocity>
        </limit>
        <dynamics>
          <damping>0</damping>
          <friction>0</friction>
          <spring_reference>0</spring_reference>
          <spring_stiffness>0</spring_stiffness>
        </dynamics>
        <use_parent_model_frame>0</use_parent_model_frame>
      </axis>
    </joint>
    <link name='toe2'>
      <pose frame=''>0.2263 -0.17098 0 0 -0 0</pose>
      <inertial>
        <pose frame=''>0 0 0 0 -0 0</pose>
        <mass>0.015</mass>
        <inertia>
          <ixx>2.5e-05</ixx>
          <ixy>0</ixy>
          <ixz>0</ixz>
          <iyy>2.5e-05</iyy>
          <iyz>0</iyz>
          <izz>2.5e-05</izz>
        </inertia>
      </inertial>
      <collision name='toe2_collision'>
        <pose frame=''>0 0 0 0 -0 0</pose>
        <geometry>
          <sphere>
            <radius>0.02</radius>
          </sphere>
        </geometry>
        <surface>
          <bounce>
            <restitution_coefficient>0</restitution_coefficient>
            <threshold>1e+06</threshold>
          </bounce>
          <friction>
            <torsional>
              <coefficient>0.3</coefficient>
            </torsional>
            <ode>
              <mu>100</mu>
              <mu2>50</mu2>
            </ode>
            <bullet>
              <rolling_friction>0.3</rolling_friction>
              <friction2>50</friction2>
            </bullet>
          </friction>
          <contact>
            <bullet>
              <kp>30000</kp>
              <kd>1000</kd>
              <split_impulse>1</split_impulse>
              <split_impulse_penetration_threshold>-0.01</split_impulse_penetration_threshold>
            </bullet>
            <ode>
              <kp>30000</kp>
              <kd>1000</kd>
            </ode>
          </contact>
        </surface>
      </collision>
      <visual name='toe2_visual'>
        <pose frame=''>0 0 0 0 -0 0</pose>
        <geometry>
          <sphere>
            <radius>0.02</radius>
          </sphere>
        </geometry>
        <material>
          <script>
            <name>Gazebo/Black</name>
            <uri>file://media/materials/scripts/gazebo.material</uri>
          </script>
        </material>
      </visual>
      <velocity_decay/>
      <self_collide>0</self_collide>
      <gravity>1</gravity>
      <velocity_decay/>
      <sensor name='toe2_contact' type='contact'>
        <plugin name='toe2_plugin' filename='libgazebo_ros_bumper.so'>
          <alwaysOn>1</alwaysOn>
          <updateRate>500</updateRate>
          <bumperTopicName>gazebo/toe2_contact_state</bumperTopicName>
          <frameName>world</frameName>
        </plugin>
        <contact>
          <collision>toe2_collision</collision>
          <topic>__default_topic__</topic>
        </contact>
        <update_rate>500</update_rate>
      </sensor>
    </link>
    <joint name='jtoe2' type='fixed'>
      <child>toe2</child>
      <parent>lower2</parent>
      <axis>
        <dynamics>
          <spring_reference>0</spring_reference>
          <spring_stiffness>0</spring_stiffness>
        </dynamics>
        <xyz>0 0 1</xyz>
        <use_parent_model_frame>0</use_parent_model_frame>
        <limit>
          <lower>-1e+16</lower>
          <upper>1e+16</upper>
        </limit>
      </axis>
      <physics>
        <ode>
          <limit>
            <cfm>0</cfm>
            <erp>0.2</erp>
          </limit>
        </ode>
      </physics>
    </joint>
    <link name='hip3'>
      <pose frame=''>-0.2263 -0.07 0 0 -0 0</pose>
      <inertial>
        <pose frame=''>0 -0.028 0 1.5708 -0 0</pose>
        <mass>0.575</mass>
        <inertia>
          <ixx>0.00074151</ixx>
          <ixy>0</ixy>
          <ixz>0</ixz>
          <iyy>0.00074151</iyy>
          <iyz>0</iyz>
          <izz>0.000869688</izz>
        </inertia>
      </inertial>
      <collision name='hip3_collision'>
        <pose frame=''>0 -0.028 0 1.5708 -0 0</pose>
        <geometry>
          <cylinder>
            <length>0.08</length>
            <radius>0.055</radius>
          </cylinder>
        </geometry>
        <surface>
          <contact>
            <ode/>
          </contact>
          <friction>
            <ode/>
          </friction>
        </surface>
      </collision>
      <visual name='hip3_visual'>
        <pose frame=''>0 -0.028 0 1.5708 -0 0</pose>
        <geometry>
          <cylinder>
            <length>0.08</length>
            <radius>0.055</radius>
          </cylinder>
        </geometry>
        <material>
          <script>
            <name>Gazebo/Grey</name>
            <uri>file://media/materials/scripts/gazebo.material</uri>
          </script>
        </material>
      </visual>
      <gravity>1</gravity>
      <velocity_decay/>
    </link>
    <joint name='11' type='revolute'>
      <child>hip3</child>
      <parent>body</parent>
      <axis>
        <xyz>1 0 0</xyz>
        <limit>
          <lower>-0.707</lower>
          <upper>0.707</upper>
          <effort>21</effort>
          <velocity>37.7</velocity>
        </limit>
        <dynamics>
          <damping>0</damping>
          <friction>0</friction>
          <spring_reference>0</spring_reference>
          <spring_stiffness>0</spring_stiffness>
        </dynamics>
        <use_parent_model_frame>0</use_parent_model_frame>
      </axis>
    </joint>
    <link name='upper3'>
      <pose frame=''>-0.2263 -0.17098 0 0 -0 0</pose>
      <inertial>
        <pose frame=''>-0.103 0.022 0 0 -0 0</pose>
        <mass>0.792</mass>
        <inertia>
          <ixx>0.000231594</ixx>
          <ixy>0</ixy>
          <ixz>0</ixz>
          <iyy>0.00300043</iyy>
          <iyz>0</iyz>
          <izz>0.00283272</izz>
        </inertia>
      </inertial>
      <collision name='upper3_collision'>
        <pose frame=''>-0.103 0.022 0 0 -0 0</pose>
        <geometry>
          <box>
            <size>0.206 0.022 0.055</size>
          </box>
        </geometry>
        <surface>
          <contact>
            <ode/>
          </contact>
          <friction>
            <ode/>
          </friction>
        </surface>
      </collision>
      <visual name='upper3_visual'>
        <pose frame=''>-0.103 0.022 0 0 -0 0</pose>
        <geometry>
          <box>
            <size>0.206 0.022 0.055</size>
          </box>
        </geometry>
        <material>
          <script>
            <name>Gazebo/DarkGrey</name>
            <uri>file://media/materials/scripts/gazebo.material</uri>
          </script>
        </material>
      </visual>
      <gravity>1</gravity>
      <velocity_decay/>
      <self_collide>0</self_collide>
    </link>
    <joint name='6' type='revolute'>
      <child>upper3</child>
      <parent>hip3</parent>
      <axis>
        <xyz>0 -1 0</xyz>
        <limit>
          <lower>-1.57</lower>
          <upper>3.14</upper>
          <effort>21</effort>
          <velocity>37.7</velocity>
        </limit>
        <dynamics>
          <damping>0</damping>
          <friction>0</friction>
          <spring_reference>0</spring_reference>
          <spring_stiffness>0</spring_stiffness>
        </dynamics>
        <use_parent_model_frame>0</use_parent_model_frame>
      </axis>
    </joint>
    <link name='lower3'>
      <pose frame=''>-0.4323 -0.17098 0 0 -0 0</pose>
      <inertial>
        <pose frame=''>0.103 0 0 0 -0 0</pose>
        <mass>0.075</mass>
        <inertia>
          <ixx>2.19313e-05</ixx>
          <ixy>0</ixy>
          <ixz>0</ixz>
          <iyy>0.000284131</iyy>
          <iyz>0</iyz>
          <izz>0.00026825</izz>
        </inertia>
      </inertial>
      <collision name='lower3_collision'>
        <pose frame=''>0.103 0 0 3.14159 1.57079 3.14159</pose>
        <geometry>
          <cylinder>
            <length>0.206</length>
            <radius>0.013</radius>
          </cylinder>
        </geometry>
        <surface>
          <contact>
            <ode/>
          </contact>
          <friction>
            <ode/>
          </friction>
        </surface>
      </collision>
      <visual name='lower3_visual'>
        <pose frame=''>0.103 0 0 3.14159 1.57079 3.14159</pose>
        <geometry>
          <cylinder>
            <length>0.206</length>
            <radius>0.013</radius>
          </cylinder>
        </geometry>
        <material>
          <script>
            <name>Gazebo/Grey</name>
            <uri>file://media/materials/scripts/gazebo.material</uri>
          </script>
        </material>
      </visual>
      <gravity>1</gravity>
      <velocity_decay/>
    </link>
    <joint name='7' type='revolute'>
      <child>lower3</child>
      <parent>upper3</parent>
      <axis>
        <xyz>0 1 0</xyz>
        <limit>
          <lower>-6.28</lower>
          <upper>6.28</upper>
          <effort>32</effort>
          <velocity>25.1</velocity>
        </limit>
        <dynamics>
          <damping>0</damping>
          <friction>0</friction>
          <spring_reference>0</spring_reference>
          <spring_stiffness>0</spring_stiffness>
        </dynamics>
        <use_parent_model_frame>0</use_parent_model_frame>
      </axis>
    </joint>
    <link name='toe3'>
      <pose frame=''>-0.2263 -0.17098 0 0 -0 0</pose>
      <inertial>
        <pose frame=''>0 0 0 0 -0 0</pose>
        <mass>0.015</mass>
        <inertia>
          <ixx>2.5e-05</ixx>
          <ixy>0</ixy>
          <ixz>0</ixz>
          <iyy>2.5e-05</iyy>
          <iyz>0</iyz>
          <izz>2.5e-05</izz>
        </inertia>
      </inertial>
      <collision name='toe3_collision'>
        <pose frame=''>0 0 0 0 -0 0</pose>
        <geometry>
          <sphere>
            <radius>0.02</radius>
          </sphere>
        </geometry>
        <surface>
          <bounce>
            <restitution_coefficient>0</restitution_coefficient>
            <threshold>1e+06</threshold>
          </bounce>
          <friction>
            <torsional>
              <coefficient>0.3</coefficient>
            </torsional>
            <ode>
              <mu>100</mu>
              <mu2>50</mu2>
            </ode>
            <bullet>
              <rolling_friction>0.3</rolling_friction>
              <friction2>50</friction2>
            </bullet>
          </friction>
          <contact>
            <bullet>
              <kp>30000</kp>
              <kd>1000</kd>
              <split_impulse>1</split_impulse>
              <split_impulse_penetration_threshold>-0.01</split_impulse_penetration_threshold>
            </bullet>
            <ode>
              <kp>30000</kp>
              <kd>1000</kd>
            </ode>
          </contact>
        </surface>
      </collision>
      <visual name='toe3_visual'>
        <pose frame=''>0 0 0 0 -0 0</pose>
        <geometry>
          <sphere>
            <radius>0.02</radius>
          </sphere>
        </geometry>
        <material>
          <script>
            <name>Gazebo/Black</name>
            <uri>file://media/materials/scripts/gazebo.material</uri>
          </script>
        </material>
      </visual>
      <velocity_decay/>
      <self_collide>0</self_collide>
      <gravity>1</gravity>
      <velocity_decay/>
      <sensor name='toe3_contact' type='contact'>
        <plugin name='toe3_plugin' filename='libgazebo_ros_bumper.so'>
          <alwaysOn>1</alwaysOn>
          <updateRate>500</updateRate>
          <bumperTopicName>gazebo/toe3_contact_state</bumperTopicName>
          <frameName>world</frameName>
        </plugin>
        <contact>
          <collision>toe3_collision</collision>
          <topic>__default_topic__</topic>
        </contact>
        <update_rate>500</update_rate>
      </sensor>
    </link>
    <joint name='jtoe3' type='fixed'>
      <child>toe3</child>
      <parent>lower3</parent>
      <axis>
        <dynamics>
          <spring_reference>0</spring_reference>
          <spring_stiffness>0</spring_stiffness>
        </dynamics>
        <xyz>0 0 1</xyz>
        <use_parent_model_frame>0</use_parent_model_frame>
        <limit>
          <lower>-1e+16</lower>
          <upper>1e+16</upper>
        </limit>
      </axis>
      <physics>
        <ode>
          <limit>
            <cfm>0</cfm>
            <erp>0.2</erp>
          </limit>
        </ode>
      </physics>
    </joint>
    <link name='hip0'>
      <pose frame=''>0.2263 0.07 0 0 -0 0</pose>
      <inertial>
        <pose frame=''>0 0.028 0 1.5708 -0 0</pose>
        <mass>0.575</mass>
        <inertia>
          <ixx>0.00074151</ixx>
          <ixy>0</ixy>
          <ixz>0</ixz>
          <iyy>0.00074151</iyy>
          <iyz>0</iyz>
          <izz>0.000869688</izz>
        </inertia>
      </inertial>
      <collision name='hip0_collision'>
        <pose frame=''>0 0.028 0 1.5708 -0 0</pose>
        <geometry>
          <cylinder>
            <length>0.08</length>
            <radius>0.055</radius>
          </cylinder>
        </geometry>
        <surface>
          <contact>
            <ode/>
          </contact>
          <friction>
            <ode/>
          </friction>
        </surface>
      </collision>
      <visual name='hip0_visual'>
        <pose frame=''>0 0.028 0 1.5708 -0 0</pose>
        <geometry>
          <cylinder>
            <length>0.08</length>
            <radius>0.055</radius>
          </cylinder>
        </geometry>
        <material>
          <script>
            <name>Gazebo/Grey</name>
            <uri>file://media/materials/scripts/gazebo.material</uri>
          </script>
        </material>
      </visual>
      <gravity>1</gravity>
      <velocity_decay/>
    </link>
    <joint name='8' type='revolute'>
      <child>hip0</child>
      <parent>body</parent>
      <axis>
        <xyz>1 0 0</xyz>
        <limit>
          <lower>-0.707</lower>
          <upper>0.707</upper>
          <effort>21</effort>
          <velocity>37.7</velocity>
        </limit>
        <dynamics>
          <damping>0</damping>
          <friction>0</friction>
          <spring_reference>0</spring_reference>
          <spring_stiffness>0</spring_stiffness>
        </dynamics>
        <use_parent_model_frame>0</use_parent_model_frame>
      </axis>
    </joint>
    <link name='upper0'>
      <pose frame=''>0.2263 0.17098 0 0 -0 0</pose>
      <inertial>
        <pose frame=''>-0.103 -0.022 0 0 -0 0</pose>
        <mass>0.792</mass>
        <inertia>
          <ixx>0.000231594</ixx>
          <ixy>0</ixy>
          <ixz>0</ixz>
          <iyy>0.00300043</iyy>
          <iyz>0</iyz>
          <izz>0.00283272</izz>
        </inertia>
      </inertial>
      <collision name='upper0_collision'>
        <pose frame=''>-0.103 -0.022 0 0 -0 0</pose>
        <geometry>
          <box>
            <size>0.206 0.022 0.055</size>
          </box>
        </geometry>
        <surface>
          <contact>
            <ode/>
          </contact>
          <friction>
            <ode/>
          </friction>
        </surface>
      </collision>
      <visual name='upper0_visual'>
        <pose frame=''>-0.103 -0.022 0 0 -0 0</pose>
        <geometry>
          <box>
            <size>0.206 0.022 0.055</size>
          </box>
        </geometry>
        <material>
          <script>
            <name>Gazebo/DarkGrey</name>
            <uri>file://media/materials/scripts/gazebo.material</uri>
          </script>
        </material>
      </visual>
      <gravity>1</gravity>
      <velocity_decay/>
      <self_collide>0</self_collide>
    </link>
    <joint name='0' type='revolute'>
      <child>upper0</child>
      <parent>hip0</parent>
      <axis>
        <xyz>0 -1 0</xyz>
        <limit>
          <lower>-1.57</lower>
          <upper>3.14</upper>
          <effort>21</effort>
          <velocity>37.7</velocity>
        </limit>
        <dynamics>
          <damping>0</damping>
          <friction>0</friction>
          <spring_reference>0</spring_reference>
          <spring_stiffness>0</spring_stiffness>
        </dynamics>
        <use_parent_model_frame>0</use_parent_model_frame>
      </axis>
    </joint>
    <link name='lower0'>
      <pose frame=''>0.0203 0.17098 0 0 -0 0</pose>
      <inertial>
        <pose frame=''>0.103 0 0 0 -0 0</pose>
        <mass>0.075</mass>
        <inertia>
          <ixx>2.19313e-05</ixx>
          <ixy>0</ixy>
          <ixz>0</ixz>
          <iyy>0.000284131</iyy>
          <iyz>0</iyz>
          <izz>0.00026825</izz>
        </inertia>
      </inertial>
      <collision name='lower0_collision'>
        <pose frame=''>0.103 0 0 3.14159 1.57079 3.14159</pose>
        <geometry>
          <cylinder>
            <length>0.206</length>
            <radius>0.013</radius>
          </cylinder>
        </geometry>
        <surface>
          <contact>
            <ode/>
          </contact>
          <friction>
            <ode/>
          </friction>
        </surface>
      </collision>
      <visual name='lower0_visual'>
        <pose frame=''>0.103 0 0 3.14159 1.57079 3.14159</pose>
        <geometry>
          <cylinder>
            <length>0.206</length>
            <radius>0.013</radius>
          </cylinder>
        </geometry>
        <material>
          <script>
            <name>Gazebo/Grey</name>
            <uri>file://media/materials/scripts/gazebo.material</uri>
          </script>
        </material>
      </visual>
      <gravity>1</gravity>
      <velocity_decay/>
    </link>
    <joint name='1' type='revolute'>
      <child>lower0</child>
      <parent>upper0</parent>
      <axis>
        <xyz>0 1 0</xyz>
        <limit>
          <lower>-6.28</lower>
          <upper>6.28</upper>
          <effort>32</effort>
          <velocity>25.1</velocity>
        </limit>
        <dynamics>
          <damping>0</damping>
          <friction>0</friction>
          <spring_reference>0</spring_reference>
          <spring_stiffness>0</spring_stiffness>
        </dynamics>
        <use_parent_model_frame>0</use_parent_model_frame>
      </axis>
    </joint>
    <link name='toe0'>
      <pose frame=''>0.2263 0.17098 0 0 -0 0</pose>
      <inertial>
        <pose frame=''>0 0 0 0 -0 0</pose>
        <mass>0.015</mass>
        <inertia>
          <ixx>2.5e-05</ixx>
          <ixy>0</ixy>
          <ixz>0</ixz>
          <iyy>2.5e-05</iyy>
          <iyz>0</iyz>
          <izz>2.5e-05</izz>
        </inertia>
      </inertial>
      <collision name='toe0_collision'>
        <pose frame=''>0 0 0 0 -0 0</pose>
        <geometry>
          <sphere>
            <radius>0.02</radius>
          </sphere>
        </geometry>
        <surface>
          <bounce>
            <restitution_coefficient>0</restitution_coefficient>
            <threshold>1e+06</threshold>
          </bounce>
          <friction>
            <torsional>
              <coefficient>0.3</coefficient>
            </torsional>
            <ode>
              <mu>100</mu>
              <mu2>50</mu2>
            </ode>
            <bullet>
              <rolling_friction>0.3</rolling_friction>
              <friction2>50</friction2>
            </bullet>
          </friction>
          <contact>
            <bullet>
              <kp>30000</kp>
              <kd>1000</kd>
              <split_impulse>1</split_impulse>
              <split_impulse_penetration_threshold>-0.01</split_impulse_penetration_threshold>
            </bullet>
            <ode>
              <kp>30000</kp>
              <kd>1000</kd>
            </ode>
          </contact>
        </surface>
      </collision>
      <visual name='toe0_visual'>
        <pose frame=''>0 0 0 0 -0 0</pose>
        <geometry>
          <sphere>
            <radius>0.02</radius>
          </sphere>
        </geometry>
        <material>
          <script>
            <name>Gazebo/Black</name>
            <uri>file://media/materials/scripts/gazebo.material</uri>
          </script>
        </material>
      </visual>
      <velocity_decay/>
      <self_collide>0</self_collide>
      <gravity>1</gravity>
      <velocity_decay/>
      <sensor name='toe0_contact' type='contact'>
        <plugin name='toe0_plugin' filename='libgazebo_ros_bumper.so'>
          <alwaysOn>1</alwaysOn>
          <updateRate>500</updateRate>
          <bumperTopicName>gazebo/toe0_contact_state</bumperTopicName>
          <frameName>world</frameName>
        </plugin>
        <contact>
          <collision>toe0_collision</collision>
          <topic>__default_topic__</topic>
        </contact>
        <update_rate>500</update_rate>
      </sensor>
    </link>
    <joint name='jtoe0' type='fixed'>
      <child>toe0</child>
      <parent>lower0</parent>
      <axis>
        <dynamics>
          <spring_reference>0</spring_reference>
          <spring_stiffness>0</spring_stiffness>
        </dynamics>
        <xyz>0 0 1</xyz>
        <use_parent_model_frame>0</use_parent_model_frame>
        <limit>
          <lower>-1e+16</lower>
          <upper>1e+16</upper>
        </limit>
      </axis>
      <physics>
        <ode>
          <limit>
            <cfm>0</cfm>
            <erp>0.2</erp>
          </limit>
        </ode>
      </physics>
    </joint>
    <link name='hip1'>
      <pose frame=''>-0.2263 0.07 0 0 -0 0</pose>
      <inertial>
        <pose frame=''>0 0.028 0 1.5708 -0 0</pose>
        <mass>0.575</mass>
        <inertia>
          <ixx>0.00074151</ixx>
          <ixy>0</ixy>
          <ixz>0</ixz>
          <iyy>0.00074151</iyy>
          <iyz>0</iyz>
          <izz>0.000869688</izz>
        </inertia>
      </inertial>
      <collision name='hip1_collision'>
        <pose frame=''>0 0.028 0 1.5708 -0 0</pose>
        <geometry>
          <cylinder>
            <length>0.08</length>
            <radius>0.055</radius>
          </cylinder>
        </geometry>
        <surface>
          <contact>
            <ode/>
          </contact>
          <friction>
            <ode/>
          </friction>
        </surface>
      </collision>
      <visual name='hip1_visual'>
        <pose frame=''>0 0.028 0 1.5708 -0 0</pose>
        <geometry>
          <cylinder>
            <length>0.08</length>
            <radius>0.055</radius>
          </cylinder>
        </geometry>
        <material>
          <script>
            <name>Gazebo/Grey</name>
            <uri>file://media/materials/scripts/gazebo.material</uri>
          </script>
        </material>
      </visual>
      <gravity>1</gravity>
      <velocity_decay/>
    </link>
    <joint name='9' type='revolute'>
      <child>hip1</child>
      <parent>body</parent>
      <axis>
        <xyz>1 0 0</xyz>
        <limit>
          <lower>-0.707</lower>
          <upper>0.707</upper>
          <effort>21</effort>
          <velocity>37.7</velocity>
        </limit>
        <dynamics>
          <damping>0</damping>
          <friction>0</friction>
          <spring_reference>0</spring_reference>
          <spring_stiffness>0</spring_stiffness>
        </dynamics>
        <use_parent_model_frame>0</use_parent_model_frame>
      </axis>
    </joint>
    <link name='upper1'>
      <pose frame=''>-0.2263 0.17098 0 0 -0 0</pose>
      <inertial>
        <pose frame=''>-0.103 -0.022 0 0 -0 0</pose>
        <mass>0.792</mass>
        <inertia>
          <ixx>0.000231594</ixx>
          <ixy>0</ixy>
          <ixz>0</ixz>
          <iyy>0.00300043</iyy>
          <iyz>0</iyz>
          <izz>0.00283272</izz>
        </inertia>
      </inertial>
      <collision name='upper1_collision'>
        <pose frame=''>-0.103 -0.022 0 0 -0 0</pose>
        <geometry>
          <box>
            <size>0.206 0.022 0.055</size>
          </box>
        </geometry>
        <surface>
          <contact>
            <ode/>
          </contact>
          <friction>
            <ode/>
          </friction>
        </surface>
      </collision>
      <visual name='upper1_visual'>
        <pose frame=''>-0.103 -0.022 0 0 -0 0</pose>
        <geometry>
          <box>
            <size>0.206 0.022 0.055</size>
          </box>
        </geometry>
        <material>
          <script>
            <name>Gazebo/DarkGrey</name>
            <uri>file://media/materials/scripts/gazebo.material</uri>
          </script>
        </material>
      </visual>
      <gravity>1</gravity>
      <velocity_decay/>
      <self_collide>0</self_collide>
    </link>
    <joint name='2' type='revolute'>
      <child>upper1</child>
      <parent>hip1</parent>
      <axis>
        <xyz>0 -1 0</xyz>
        <limit>
          <lower>-1.57</lower>
          <upper>3.14</upper>
          <effort>21</effort>
          <velocity>37.7</velocity>
        </limit>
        <dynamics>
          <damping>0</damping>
          <friction>0</friction>
          <spring_reference>0</spring_reference>
          <spring_stiffness>0</spring_stiffness>
        </dynamics>
        <use_parent_model_frame>0</use_parent_model_frame>
      </axis>
    </joint>
    <link name='lower1'>
      <pose frame=''>-0.4323 0.17098 0 0 -0 0</pose>
      <inertial>
        <pose frame=''>0.103 0 0 0 -0 0</pose>
        <mass>0.075</mass>
        <inertia>
          <ixx>2.19313e-05</ixx>
          <ixy>0</ixy>
          <ixz>0</ixz>
          <iyy>0.000284131</iyy>
          <iyz>0</iyz>
          <izz>0.00026825</izz>
        </inertia>
      </inertial>
      <collision name='lower1_collision'>
        <pose frame=''>0.103 0 0 3.14159 1.57079 3.14159</pose>
        <geometry>
          <cylinder>
            <length>0.206</length>
            <radius>0.013</radius>
          </cylinder>
        </geometry>
        <surface>
          <contact>
            <ode/>
          </contact>
          <friction>
            <ode/>
          </friction>
        </surface>
      </collision>
      <visual name='lower1_visual'>
        <pose frame=''>0.103 0 0 3.14159 1.57079 3.14159</pose>
        <geometry>
          <cylinder>
            <length>0.206</length>
            <radius>0.013</radius>
          </cylinder>
        </geometry>
        <material>
          <script>
            <name>Gazebo/Grey</name>
            <uri>file://media/materials/scripts/gazebo.material</uri>
          </script>
        </material>
      </visual>
      <gravity>1</gravity>
      <velocity_decay/>
    </link>
    <joint name='3' type='revolute'>
      <child>lower1</child>
      <parent>upper1</parent>
      <axis>
        <xyz>0 1 0</xyz>
        <limit>
          <lower>-6.28</lower>
          <upper>6.28</upper>
          <effort>32</effort>
          <velocity>25.1</velocity>
        </limit>
        <dynamics>
          <damping>0</damping>
          <friction>0</friction>
          <spring_reference>0</spring_reference>
          <spring_stiffness>0</spring_stiffness>
        </dynamics>
        <use_parent_model_frame>0</use_parent_model_frame>
      </axis>
    </joint>
    <link name='toe1'>
      <pose frame=''>-0.2263 0.17098 0 0 -0 0</pose>
      <inertial>
        <pose frame=''>0 0 0 0 -0 0</pose>
        <mass>0.015</mass>
        <inertia>
          <ixx>2.5e-05</ixx>
          <ixy>0</ixy>
          <ixz>0</ixz>
          <iyy>2.5e-05</iyy>
          <iyz>0</iyz>
          <izz>2.5e-05</izz>
        </inertia>
      </inertial>
      <collision name='toe1_collision'>
        <pose frame=''>0 0 0 0 -0 0</pose>
        <geometry>
          <sphere>
            <radius>0.02</radius>
          </sphere>
        </geometry>
        <surface>
          <bounce>
            <restitution_coefficient>0</restitution_coefficient>
            <threshold>1e+06</threshold>
          </bounce>
          <friction>
            <torsional>
              <coefficient>0.3</coefficient>
            </torsional>
            <ode>
              <mu>100</mu>
              <mu2>50</mu2>
            </ode>
            <bullet>
              <rolling_friction>0.3</rolling_friction>
              <friction2>50</friction2>
            </bullet>
          </friction>
          <contact>
            <bullet>
              <kp>30000</kp>
              <kd>1000</kd>
              <split_impulse>1</split_impulse>
              <split_impulse_penetration_threshold>-0.01</split_impulse_penetration_threshold>
            </bullet>
            <ode>
              <kp>30000</kp>
              <kd>1000</kd>
            </ode>
          </contact>
        </surface>
      </collision>
      <visual name='toe1_visual'>
        <pose frame=''>0 0 0 0 -0 0</pose>
        <geometry>
          <sphere>
            <radius>0.02</radius>
          </sphere>
        </geometry>
        <material>
          <script>
            <name>Gazebo/Black</name>
            <uri>file://media/materials/scripts/gazebo.material</uri>
          </script>
        </material>
      </visual>
      <velocity_decay/>
      <self_collide>0</self_collide>
      <gravity>1</gravity>
      <velocity_decay/>
      <sensor name='toe1_contact' type='contact'>
        <plugin name='toe1_plugin' filename='libgazebo_ros_bumper.so'>
          <alwaysOn>1</alwaysOn>
          <updateRate>500</updateRate>
          <bumperTopicName>gazebo/toe1_contact_state</bumperTopicName>
          <frameName>world</frameName>
        </plugin>
        <contact>
          <collision>toe1_collision</collision>
          <topic>__default_topic__</topic>
        </contact>
        <update_rate>500</update_rate>
      </sensor>
    </link>
    <joint name='jtoe1' type='fixed'>
      <child>toe1</child>
      <parent>lower1</parent>
      <axis>
        <dynamics>
          <spring_reference>0</spring_reference>
          <spring_stiffness>0</spring_stiffness>
        </dynamics>
        <xyz>0 0 1</xyz>
        <use_parent_model_frame>0</use_parent_model_frame>
        <limit>
          <lower>-1e+16</lower>
          <upper>1e+16</upper>
        </limit>
      </axis>
      <physics>
        <ode>
          <limit>
            <cfm>0</cfm>
            <erp>0.2</erp>
          </limit>
        </ode>
      </physics>
    </joint>
    <link name='tail_link_0'>
      <pose frame=''>0 0 0 0 -0 0</pose>
      <inertial>
        <pose frame=''>0 0 0.073467 0 -0 0</pose>
        <mass>0.001</mass>
        <inertia>
          <ixx>2.77778e-06</ixx>
          <ixy>0</ixy>
          <ixz>0</ixz>
          <iyy>2.77778e-06</iyy>
          <iyz>0</iyz>
          <izz>2.77778e-06</izz>
        </inertia>
      </inertial>
      <visual name='tail_link_0_visual'>
        <pose frame=''>0 0 0.073467 0 -0 0</pose>
        <geometry>
          <cylinder>
            <length>0.146933</length>
            <radius>0.02</radius>
          </cylinder>
        </geometry>
        <material>
          <script>
            <name>Gazebo/Gray</name>
            <uri>file://media/materials/scripts/gazebo.material</uri>
          </script>
        </material>
      </visual>
      <gravity>1</gravity>
      <velocity_decay/>
    </link>
    <joint name='body_tail_joint_0' type='revolute'>
      <child>tail_link_0</child>
      <parent>body</parent>
      <axis>
        <xyz>0 1 0</xyz>
        <limit>
          <lower>-1.57</lower>
          <upper>1.57</upper>
          <effort>50</effort>
          <velocity>40</velocity>
        </limit>
        <dynamics>
          <damping>0</damping>
          <friction>0</friction>
          <spring_reference>0</spring_reference>
          <spring_stiffness>0</spring_stiffness>
        </dynamics>
        <use_parent_model_frame>0</use_parent_model_frame>
      </axis>
    </joint>
    <link name='tail_link_1'>
      <pose frame=''>0 0 0.146933 0 -0 0</pose>
      <inertial>
        <pose frame=''>0 0 0.073467 0 -0 0</pose>
        <mass>0.001</mass>
        <inertia>
          <ixx>2.77778e-06</ixx>
          <ixy>0</ixy>
          <ixz>0</ixz>
          <iyy>2.77778e-06</iyy>
          <iyz>0</iyz>
          <izz>2.77778e-06</izz>
        </inertia>
      </inertial>
      <visual name='tail_link_1_visual'>
        <pose frame=''>0 0 0.073467 0 -0 0</pose>
        <geometry>
          <cylinder>
            <length>0.146933</length>
            <radius>0.02</radius>
          </cylinder>
        </geometry>
        <material>
          <script>
            <name>Gazebo/Gray</name>
            <uri>file://media/materials/scripts/gazebo.material</uri>
          </script>
        </material>
      </visual>
      <gravity>1</gravity>
      <velocity_decay/>
    </link>
    <joint name='body_tail_joint_1' type='revolute'>
      <child>tail_link_1</child>
      <parent>tail_link_0</parent>
      <axis>
        <xyz>0 1 0</xyz>
        <limit>
          <lower>-1.57</lower>
          <upper>1.57</upper>
          <effort>50</effort>
          <velocity>40</velocity>
        </limit>
        <dynamics>
          <damping>0</damping>
          <friction>0</friction>
          <spring_reference>0</spring_reference>
          <spring_stiffness>0</spring_stiffness>
        </dynamics>
        <use_parent_model_frame>0</use_parent_model_frame>
      </axis>
    </joint>
    <link name='tail_link_2'>
      <pose frame=''>0 0 0.293867 0 -0 0</pose>
      <inertial>
        <pose frame=''>0 0 0.073467 0 -0 0</pose>
        <mass>0.001</mass>
        <inertia>
          <ixx>2.77778e-06</ixx>
          <ixy>0</ixy>
          <ixz>0</ixz>
          <iyy>2.77778e-06</iyy>
          <iyz>0</iyz>
          <izz>2.77778e-06</izz>
        </inertia>
      </inertial>
      <visual name='tail_link_2_visual'>
        <pose frame=''>0 0 0.073467 0 -0 0</pose>
        <geometry>
          <cylinder>
            <length>0.146933</length>
            <radius>0.02</radius>
          </cylinder>
        </geometry>
        <material>
          <script>
            <name>Gazebo/Gray</name>
            <uri>file://media/materials/scripts/gazebo.material</uri>
          </script>
        </material>
      </visual>
      <gravity>1</gravity>
      <velocity_decay/>
    </link>
    <joint name='body_tail_joint_2' type='revolute'>
      <child>tail_link_2</child>
      <parent>tail_link_1</parent>
      <axis>
        <xyz>0 1 0</xyz>
        <limit>
          <lower>-1.57</lower>
          <upper>1.57</upper>
          <effort>50</effort>
          <velocity>40</velocity>
        </limit>
        <dynamics>
          <damping>0</damping>
          <friction>0</friction>
          <spring_reference>0</spring_reference>
          <spring_stiffness>0</spring_stiffness>
        </dynamics>
        <use_parent_model_frame>0</use_parent_model_frame>
      </axis>
    </joint>
    <link name='tail_link_3'>
      <pose frame=''>0 0 0.4408 0 -0 0</pose>
      <inertial>
        <pose frame=''>0 0 0.073467 0 -0 0</pose>
        <mass>0.001</mass>
        <inertia>
          <ixx>2.77778e-06</ixx>
          <ixy>0</ixy>
          <ixz>0</ixz>
          <iyy>2.77778e-06</iyy>
          <iyz>0</iyz>
          <izz>2.77778e-06</izz>
        </inertia>
      </inertial>
      <visual name='tail_link_3_visual'>
        <pose frame=''>0 0 0.073467 0 -0 0</pose>
        <geometry>
          <cylinder>
            <length>0.146933</length>
            <radius>0.02</radius>
          </cylinder>
        </geometry>
        <material>
          <script>
            <name>Gazebo/Gray</name>
            <uri>file://media/materials/scripts/gazebo.material</uri>
          </script>
        </material>
      </visual>
      <gravity>1</gravity>
      <velocity_decay/>
    </link>
    <joint name='body_tail_joint_3' type='revolute'>
      <child>tail_link_3</child>
      <parent>tail_link_2</parent>
      <axis>
        <xyz>0 1 0</xyz>
        <limit>
          <lower>-1.57</lower>
          <upper>1.57</upper>
          <effort>50</effort>
          <velocity>40</velocity>
        </limit>
        <dynamics>
          <damping>0</damping>
          <friction>0</friction>
          <spring_reference>0</spring_reference>
          <spring_stiffness>0</spring_stiffness>
        </dynamics>
        <use_parent_model_frame>0</use_parent_model_frame>
      </axis>
    </joint>
    <link name='tail_link_4'>
      <pose frame=''>0 0 0.587733 0 -0 0</pose>
      <inertial>
        <pose frame=''>0 0 0.073467 0 -0 0</pose>
        <mass>0.001</mass>
        <inertia>
          <ixx>2.77778e-06</ixx>
          <ixy>0</ixy>
          <ixz>0</ixz>
          <iyy>2.77778e-06</iyy>
          <iyz>0</iyz>
          <izz>2.77778e-06</izz>
        </inertia>
      </inertial>
      <visual name='tail_link_4_visual'>
        <pose frame=''>0 0 0.073467 0 -0 0</pose>
        <geometry>
          <cylinder>
            <length>0.146933</length>
            <radius>0.02</radius>
          </cylinder>
        </geometry>
        <material>
          <script>
            <name>Gazebo/Gray</name>
            <uri>file://media/materials/scripts/gazebo.material</uri>
          </script>
        </material>
      </visual>
      <gravity>1</gravity>
      <velocity_decay/>
    </link>
    <joint name='body_tail_joint_4' type='revolute'>
      <child>tail_link_4</child>
      <parent>tail_link_3</parent>
      <axis>
        <xyz>0 1 0</xyz>
        <limit>
          <lower>-1.57</lower>
          <upper>1.57</upper>
          <effort>50</effort>
          <velocity>40</velocity>
        </limit>
        <dynamics>
          <damping>0</damping>
          <friction>0</friction>
          <spring_reference>0</spring_reference>
          <spring_stiffness>0</spring_stiffness>
        </dynamics>
        <use_parent_model_frame>0</use_parent_model_frame>
      </axis>
    </joint>
    <link name='tail_link_5'>
      <pose frame=''>0 0 0.734667 0 -0 0</pose>
      <inertial>
        <pose frame=''>0 0 0.146668 0 -0 0</pose>
        <mass>0.2774</mass>
        <inertia>
          <ixx>0.000284556</ixx>
          <ixy>0</ixy>
          <ixz>0</ixz>
          <iyy>0.000284556</iyy>
          <iyz>0</iyz>
          <izz>0.000279178</izz>
        </inertia>
      </inertial>
      <collision name='tail_link_5_fixed_joint_lump__tail_mass_collision'>
        <pose frame=''>0 0 0.146933 0 -0 0</pose>
        <geometry>
          <sphere>
            <radius>0.04</radius>
          </sphere>
        </geometry>
        <surface>
          <contact>
            <ode/>
          </contact>
          <friction>
            <ode/>
          </friction>
        </surface>
      </collision>
      <visual name='tail_link_5_visual'>
        <pose frame=''>0 0 0.073467 0 -0 0</pose>
        <geometry>
          <cylinder>
            <length>0.146933</length>
            <radius>0.02</radius>
          </cylinder>
        </geometry>
        <material>
          <script>
            <name>Gazebo/Gray</name>
            <uri>file://media/materials/scripts/gazebo.material</uri>
          </script>
        </material>
      </visual>
      <visual name='tail_link_5_fixed_joint_lump__tail_mass_visual_1'>
        <pose frame=''>0 0 0.146933 0 -0 0</pose>
        <geometry>
          <sphere>
            <radius>0.04</radius>
          </sphere>
        </geometry>
        <material>
          <script>
            <name>Gazebo/Gray</name>
            <uri>file://media/materials/scripts/gazebo.material</uri>
          </script>
        </material>
      </visual>
      <velocity_decay/>
      <gravity>1</gravity>
      <velocity_decay/>
    </link>
    <joint name='body_tail_joint_5' type='revolute'>
      <child>tail_link_5</child>
      <parent>tail_link_4</parent>
      <axis>
        <xyz>0 1 0</xyz>
        <limit>
          <lower>-1.57</lower>
          <upper>1.57</upper>
          <effort>50</effort>
          <velocity>40</velocity>
        </limit>
        <dynamics>
          <damping>0</damping>
          <friction>0</friction>
          <spring_reference>0</spring_reference>
          <spring_stiffness>0</spring_stiffness>
        </dynamics>
        <use_parent_model_frame>0</use_parent_model_frame>
      </axis>
    </joint>
    <static>0</static>
    <plugin name='gazebo_ros_control' filename='libgazebo_ros_control.so'>
      <robotNamespace>/spirit</robotNamespace>
      <controlPeriod>0.002</controlPeriod>
    </plugin>
    <plugin name='ground_truth_estimator' filename='libground_truth_estimator.so'>
      <updateRateHz>500.0</updateRateHz>
    </plugin>
  </model>
</sdf>
