<?xml version="1.0" encoding="utf-8"?>
<!-- =================================================================================== -->
<!-- |    This document was autogenerated by xacro from pupperv2_description_lite.urdf.xacro | -->
<!-- |    EDITING THIS FILE BY HAND IS NOT RECOMMENDED                                 | -->
<!-- =================================================================================== -->
<!-- This URDF was automatically created by SolidWorks to URDF Exporter! Originally created by Stephen Brawner (brawner@gmail.com) 
     Commit Version: 1.5.1-0-g916b5db  Build Version: 1.5.7152.31018
     For more information, please see http://wiki.ros.org/sw_urdf_exporter -->
<robot name="pupperv2_description">
  <!-- Enable Gazebo ROS Control -->
  <gazebo>
    <plugin filename="libgazebo_ros_control.so" name="gazebo_ros_control">
      <legacyModeNS>true</legacyModeNS>
      <robotSimType>gazebo_ros_control/DefaultRobotHWSim</robotSimType>
    </plugin>
  </gazebo>
  <joint name="hokuyo_joint" type="fixed">
    <origin rpy="0 0 0" xyz="0.0 0.0 0.08661"/>
    <parent link="base_link"/>
    <child link="hokuyo_frame"/>
  </joint>
  <link name="hokuyo_frame">
    <inertial>
      <mass value="0.270"/>
      <origin rpy="0 0 0" xyz="0 0 0"/>
      <inertia ixx="2.632e-4" ixy="0" ixz="0" iyy="2.632e-4" iyz="0" izz="1.62e-4"/>
    </inertial>
    <visual>
      <origin rpy="0 0 0" xyz="0 0 0"/>
      <geometry>
        <mesh filename="package://hector_sensors_description/meshes/hokuyo_utm30lx/hokuyo_utm_30lx.dae"/>
      </geometry>
    </visual>
    <collision>
      <origin rpy="0 0 0" xyz="0 0 -0.0115"/>
      <geometry>
        <box size="0.058 0.058 0.087"/>
        <!--<mesh filename="package://hector_sensors_description/meshes/hokuyo_utm30lx/hokuyo_utm_30lx.stl"/>-->
      </geometry>
    </collision>
  </link>
  <gazebo reference="hokuyo_frame">
    <sensor name="hokuyo" type="ray">
      <always_on>true</always_on>
      <update_rate>30</update_rate>
      <pose>0 0 0 0 0 0</pose>
      <visualize>false</visualize>
      <ray>
        <scan>
          <horizontal>
            <samples>1040</samples>
            <resolution>1</resolution>
            <min_angle>2.26892802759</min_angle>
            <max_angle>-2.26892802759</max_angle>
          </horizontal>
        </scan>
        <range>
          <min>0.2</min>
          <max>30.0</max>
          <resolution>0.01</resolution>
        </range>
        <noise>
          <type>gaussian</type>
          <mean>0.0</mean>
          <stddev>0.004</stddev>
        </noise>
      </ray>
      <plugin filename="libgazebo_ros_laser.so" name="gazebo_ros_hokuyo_controller">
        <topicName>scan</topicName>
        <frameName>hokuyo_frame</frameName>
      </plugin>
    </sensor>
  </gazebo>
  <joint name="camera_joint" type="fixed">
    <origin rpy="0 0 0" xyz="0.13641 0.0 -0.05661"/>
    <parent link="base_link"/>
    <child link="camera_link"/>
  </joint>
  <link name="camera_link">
    <inertial>
      <mass value="0.200"/>
      <origin rpy="0 0 0" xyz="0 0 0"/>
      <inertia ixx="5.8083e-4" ixy="0" ixz="0" iyy="3.0833e-5" iyz="0" izz="5.9083e-4"/>
    </inertial>
    <visual>
      <origin rpy="0 0 0" xyz="0 0 0"/>
      <geometry>
        <mesh filename="package://hector_sensors_description/meshes/asus_camera/asus_camera_simple.dae"/>
      </geometry>
    </visual>
    <!--        
       <collision>
          <origin xyz="0 0 0" rpy="0 0 0" />
          <geometry>
            <box size="0.035 0.185 0.025"/>
          </geometry>
        </collision>
        -->
    <collision>
      <origin rpy="0 0 0" xyz="0 0 0"/>
      <geometry>
        <mesh filename="package://hector_sensors_description/meshes/asus_camera/asus_camera_simple.dae"/>
      </geometry>
    </collision>
  </link>
  <joint name="camera_depth_joint" type="fixed">
    <origin rpy="0 0 0" xyz="0.0 0.049 0.0"/>
    <parent link="camera_link"/>
    <child link="camera_depth_frame"/>
  </joint>
  <link name="camera_depth_frame"/>
  <joint name="camera_depth_optical_joint" type="fixed">
    <origin rpy="-1.57079632679 0.0 -1.57079632679" xyz="0 0 0"/>
    <parent link="camera_depth_frame"/>
    <child link="camera_depth_optical_frame"/>
  </joint>
  <link name="camera_depth_optical_frame"/>
  <joint name="camera_rgb_joint" type="fixed">
    <origin rpy="0 0 0" xyz="0.0 0.022 0.0"/>
    <parent link="camera_link"/>
    <child link="camera_rgb_frame"/>
  </joint>
  <link name="camera_rgb_frame"/>
  <joint name="camera_rgb_optical_joint" type="fixed">
    <origin rpy="-1.57079632679 0.0 -1.57079632679" xyz="0 0 0"/>
    <parent link="camera_rgb_frame"/>
    <child link="camera_rgb_optical_frame"/>
  </joint>
  <link name="camera_rgb_optical_frame"/>
  <!-- ASUS Xtion PRO camera for simulation -->
  <gazebo reference="camera_depth_frame">
    <sensor name="camera" type="depth">
      <update_rate>20</update_rate>
      <camera>
        <horizontal_fov>1.09606677025</horizontal_fov>
        <image>
          <format>R8G8B8</format>
          <width>640</width>
          <height>480</height>
        </image>
        <clip>
          <near>0.5</near>
          <far>9</far>
        </clip>
      </camera>
      <plugin filename="libgazebo_ros_openni_kinect.so" name="camera_camera_controller">
        <imageTopicName>camera/rgb/image_raw</imageTopicName>
        <cameraInfoTopicName>camera/rgb/camera_info</cameraInfoTopicName>
        <depthImageTopicName>camera/depth/image_raw</depthImageTopicName>
        <depthImageCameraInfoTopicName>camera/depth/camera_info</depthImageCameraInfoTopicName>
        <pointCloudTopicName>camera/depth/points</pointCloudTopicName>
        <frameName>camera_depth_optical_frame</frameName>
      </plugin>
    </sensor>
  </gazebo>
  <gazebo>
    <plugin filename="libhector_gazebo_ros_imu.so" name="imu_controller">
      <updateRate>50.0</updateRate>
      <bodyName>imu_link</bodyName>
      <topicName>imu/data</topicName>
      <accelDrift>0.005 0.005 0.005</accelDrift>
      <accelGaussianNoise>0.005 0.005 0.005</accelGaussianNoise>
      <rateDrift>0.005 0.005 0.005 </rateDrift>
      <rateGaussianNoise>0.005 0.005 0.005 </rateGaussianNoise>
      <headingDrift>0.005</headingDrift>
      <headingGaussianNoise>0.005</headingGaussianNoise>
    </plugin>
  </gazebo>
  <link name="imu_link">
    <inertial>
      <mass value="0.001"/>
      <origin rpy="0 0 0" xyz="0 0 0"/>
      <inertia ixx="1e-09" ixy="0.0" ixz="0.0" iyy="1e-09" iyz="0.0" izz="1e-09"/>
    </inertial>
  </link>
  <joint name="imu_joint" type="fixed">
    <parent link="base_link"/>
    <child link="imu_link"/>
  </joint>
  <!-- <xacro:include filename="$(find velodyne_description)/urdf/VLP-16.urdf.xacro"/>
        <xacro:VLP-16 parent="${base_name}" name="velodyne" topic="velodyne_points" hz="10" samples="1024" gpu="false" lasers="16" max_range="100">
            <origin xyz="0 0 ${base_height / 2}" rpy="0 0 0" />
        </xacro:VLP-16>
        <xacro:include filename="$(find champ_arm_description)/urdf/champ_arm.urdf.xacro" />
        <xacro:champ_arm parent="${base_name}">
            <origin xyz="0.07 0.0 ${base_height / 2}" rpy="0 0 0"/>
        </xacro:champ_arm> -->
  <gazebo>
    <plugin filename="libgazebo_ros_p3d.so" name="p3d_base_controller">
      <alwaysOn>true</alwaysOn>
      <updateRate>10.0</updateRate>
      <bodyName>base_link</bodyName>
      <topicName>odom/ground_truth</topicName>
      <gaussianNoise>0.01</gaussianNoise>
      <frameName>world</frameName>
      <xyzOffsets>0 0 0</xyzOffsets>
      <rpyOffsets>0 0 0</rpyOffsets>
    </plugin>
  </gazebo>
  <!-- Solidworks to URDF (Mostly) -->
  <link name="base_link">
    <visual>
      <origin rpy="0 0 0" xyz="0 0 0"/>
      <geometry>
        <mesh filename="package://pupperv2_description/obj_meshes/Cube003.obj"/>
      </geometry>
      <material name="">
        <color rgba="0.75294 0.75294 0.75294 1"/>
      </material>
    </visual>
    <collision>
      <origin rpy="0 0 0" xyz="0 0 0"/>
      <geometry>
        <mesh filename="package://pupperv2_description/obj_meshes/Cube003.obj"/>
      </geometry>
    </collision>
  </link>
  <link name="base_inertia">
    <inertial>
      <origin rpy="0 0 0" xyz="4.4516E-07 -2.0991E-07 3.7751E-06"/>
      <mass value="0.37691"/>
      <inertia ixx="0.00038775" ixy="1.1873E-06" ixz="-9.237E-07" iyy="0.00085802" iyz="1.7272E-07" izz="0.0010086"/>
    </inertial>
  </link>
  <joint name="base_link_base_inertia" type="fixed">
    <parent link="base_link"/>
    <child link="base_inertia"/>
  </joint>
  <link name="FL_hip">
    <inertial>
      <origin rpy="0 0 0" xyz="0.01877 0.0032945 0.00038989"/>
      <mass value="0.032035"/>
      <inertia ixx="5.9933E-06" ixy="4.4808E-07" ixz="2.4371E-10" iyy="2.9538E-06" iyz="6.1996E-08" izz="5.7278E-06"/>
    </inertial>
    <visual>
      <origin rpy="1.57079632679 0 0" xyz="0.00795 0.00329 0.00039"/>
      <geometry>
        <!--mesh
          filename="package://pupperv2_description/meshes/FL_hip.STL" /-->
        <cylinder length="0.0483" radius="0.0152"/>
      </geometry>
      <material name="">
        <color rgba="0.75294 0.75294 0.75294 1"/>
      </material>
    </visual>
    <collision>
      <origin rpy="0 0 0" xyz="0 0 0"/>
      <geometry>
        <!--mesh
          filename="package://pupperv2_description/meshes/FL_hip.STL" /-->
        <box size="0.03569 0.0483 0.025"/>
      </geometry>
    </collision>
  </link>
  <joint name="base_link_FL_hip" type="revolute">
    <origin rpy="0 0 0" xyz="0.036007 0.0466 0.00461"/>
    <parent link="base_link"/>
    <child link="FL_hip"/>
    <axis xyz="1 0 0"/>
    <limit effort="100" lower="-0.7854" upper="0.7854" velocity="2.5"/>
  </joint>
  <link name="FL_upper_leg">
    <inertial>
      <origin rpy="0 0 0" xyz="0.00011578 0.025203 -0.048064"/>
      <mass value="0.054665"/>
      <inertia ixx="2.4386E-05" ixy="1.682E-10" ixz="2.6061E-07" iyy="2.3437E-05" iyz="2.7137E-07" izz="6.6679E-06"/>
    </inertial>
    <visual>
      <origin rpy="0 0 0" xyz="0 0 0"/>
      <geometry>
        <mesh filename="package://pupperv2_description/meshes/FL_upper_leg.STL"/>
      </geometry>
      <material name="">
        <color rgba="0.75294 0.75294 0.75294 1"/>
      </material>
    </visual>
    <collision>
      <origin rpy="0 0 0" xyz="0 0 0"/>
      <geometry>
        <mesh filename="package://pupperv2_description/meshes/FL_upper_leg.STL"/>
      </geometry>
    </collision>
  </link>
  <joint name="FL_hip_FL_upper_leg" type="revolute">
    <origin rpy="0 0 0" xyz="0.01525 0.02535 0"/>
    <parent link="FL_hip"/>
    <child link="FL_upper_leg"/>
    <axis xyz="0 1 0"/>
    <limit effort="100" lower="-1.309" upper="4.4506" velocity="2.5"/>
  </joint>
  <link name="FL_lower_leg">
    <inertial>
      <origin rpy="0 0 0" xyz="0.00028051 0.0039614 -0.040452"/>
      <mass value="0.016718"/>
      <inertia ixx="1.8319E-05" ixy="-1.9835E-08" ixz="2.3453E-07" iyy="1.8546E-05" iyz="6.7626E-07" izz="5.5282E-07"/>
    </inertial>
    <visual>
      <origin rpy="0 0 0" xyz="0 0 0"/>
      <geometry>
        <mesh filename="package://pupperv2_description/meshes/FL_lower_leg.STL"/>
      </geometry>
      <material name="">
        <color rgba="0.75294 0.75294 0.75294 1"/>
      </material>
    </visual>
    <collision>
      <origin rpy="0 0 0" xyz="0 0 0"/>
      <geometry>
        <mesh filename="package://pupperv2_description/meshes/FL_lower_leg.STL"/>
      </geometry>
    </collision>
  </link>
  <joint name="FL_upper_leg_FL_lower_leg" type="revolute">
    <origin rpy="0 0 0" xyz="0 0 -0.08"/>
    <parent link="FL_upper_leg"/>
    <child link="FL_lower_leg"/>
    <axis xyz="0 1 0"/>
    <limit effort="100" lower="-2.8798" upper="2.8798" velocity="2.5"/>
  </joint>
  <link name="FL_toe">
    <inertial>
      <origin rpy="0 0 0" xyz="-0.002296 2.7756E-17 -0.0027362"/>
      <mass value="0.0018099"/>
      <inertia ixx="5.2131E-08" ixy="-1.9882E-24" ixz="1.137E-08" iyy="4.259E-08" iyz="-9.4483E-25" izz="5.6141E-08"/>
    </inertial>
    <visual>
      <origin rpy="0 0 0" xyz="0 0 0"/>
      <geometry>
        <mesh filename="package://pupperv2_description/meshes/FL_toe.STL"/>
      </geometry>
      <material name="">
        <color rgba="0.15294 0.15294 0.15294 1"/>
      </material>
    </visual>
    <collision>
      <origin rpy="0 0 0" xyz="0 0 0"/>
      <geometry>
        <mesh filename="package://pupperv2_description/meshes/FL_toe.STL"/>
      </geometry>
    </collision>
  </link>
  <joint name="FL_lower_leg_FL_toe" type="fixed">
    <origin rpy="0 0 0" xyz="0 0.008325 -0.11"/>
    <parent link="FL_lower_leg"/>
    <child link="FL_toe"/>
    <axis xyz="0.64279 0 0.76604"/>
  </joint>
  <link name="RL_hip">
    <inertial>
      <origin rpy="0 0 0" xyz="-0.022505 0.0032945 0.00038989"/>
      <mass value="0.032035"/>
      <inertia ixx="5.9933E-06" ixy="4.4808E-07" ixz="2.4371E-10" iyy="2.9538E-06" iyz="6.1996E-08" izz="5.7278E-06"/>
    </inertial>
    <visual>
      <origin rpy="0 0 0" xyz="0 0 0"/>
      <geometry>
        <mesh filename="package://pupperv2_description/meshes/RL_hip.STL"/>
      </geometry>
      <material name="">
        <color rgba="0.75294 0.75294 0.75294 1"/>
      </material>
    </visual>
    <collision>
      <origin rpy="0 0 0" xyz="0 0 0"/>
      <geometry>
        <mesh filename="package://pupperv2_description/meshes/RL_hip.STL"/>
      </geometry>
    </collision>
  </link>
  <joint name="base_link_RL_hip" type="revolute">
    <origin rpy="0 0 0" xyz="-0.12272 0.0466 0.00461"/>
    <parent link="base_link"/>
    <child link="RL_hip"/>
    <axis xyz="1 0 0"/>
    <limit effort="100" lower="-0.7854" upper="0.7854" velocity="2.5"/>
  </joint>
  <link name="RL_upper_leg">
    <inertial>
      <origin rpy="0 0 0" xyz="0.00011578 0.025203 -0.048064"/>
      <mass value="0.054665"/>
      <inertia ixx="2.4386E-05" ixy="1.682E-10" ixz="2.6061E-07" iyy="2.3437E-05" iyz="2.7137E-07" izz="6.6679E-06"/>
    </inertial>
    <visual>
      <origin rpy="0 0 0" xyz="0 0 0"/>
      <geometry>
        <mesh filename="package://pupperv2_description/meshes/RL_upper_leg.STL"/>
      </geometry>
      <material name="">
        <color rgba="0.75294 0.75294 0.75294 1"/>
      </material>
    </visual>
    <collision>
      <origin rpy="0 0 0" xyz="0 0 0"/>
      <geometry>
        <mesh filename="package://pupperv2_description/meshes/RL_upper_leg.STL"/>
      </geometry>
    </collision>
  </link>
  <joint name="RL_hip_RL_upper_leg" type="revolute">
    <origin rpy="0 0.0011305 0" xyz="-0.026025 0.02535 0"/>
    <parent link="RL_hip"/>
    <child link="RL_upper_leg"/>
    <axis xyz="0 1 0"/>
    <limit effort="100" lower="-1.309" upper="4.4506" velocity="2.5"/>
  </joint>
  <link name="RL_lower_leg">
    <inertial>
      <origin rpy="0 0 0" xyz="0.00028051 0.0039614 -0.040452"/>
      <mass value="0.016718"/>
      <inertia ixx="1.8319E-05" ixy="-1.9835E-08" ixz="2.3453E-07" iyy="1.8546E-05" iyz="6.7626E-07" izz="5.5282E-07"/>
    </inertial>
    <visual>
      <origin rpy="0 0 0" xyz="0 0 0"/>
      <geometry>
        <mesh filename="package://pupperv2_description/meshes/RL_lower_leg.STL"/>
      </geometry>
      <material name="">
        <color rgba="0.75294 0.75294 0.75294 1"/>
      </material>
    </visual>
    <collision>
      <origin rpy="0 0 0" xyz="0 0 0"/>
      <geometry>
        <mesh filename="package://pupperv2_description/meshes/RL_lower_leg.STL"/>
      </geometry>
    </collision>
  </link>
  <joint name="RL_upper_leg_RL_lower_leg" type="revolute">
    <origin rpy="0 -0.0011305 0" xyz="0 0 -0.08"/>
    <parent link="RL_upper_leg"/>
    <child link="RL_lower_leg"/>
    <axis xyz="0 1 0"/>
    <limit effort="100" lower="-2.8798" upper="2.8798" velocity="2.5"/>
  </joint>
  <link name="RL_toe">
    <inertial>
      <origin rpy="0 0 0" xyz="-0.002296 0 -0.0027362"/>
      <mass value="0.0018099"/>
      <inertia ixx="5.2131E-08" ixy="-1.082E-24" ixz="1.137E-08" iyy="4.259E-08" iyz="-9.2836E-25" izz="5.6141E-08"/>
    </inertial>
    <visual>
      <origin rpy="0 0 0" xyz="0 0 0"/>
      <geometry>
        <mesh filename="package://pupperv2_description/meshes/RL_toe.STL"/>
      </geometry>
      <material name="">
        <color rgba="0.15294 0.15294 0.15294 1"/>
      </material>
    </visual>
    <collision>
      <origin rpy="0 0 0" xyz="0 0 0"/>
      <geometry>
        <mesh filename="package://pupperv2_description/meshes/RL_toe.STL"/>
      </geometry>
    </collision>
  </link>
  <joint name="RL_lower_leg_RL_toe" type="fixed">
    <origin rpy="0 0 0" xyz="0 0.008325 -0.11"/>
    <parent link="RL_lower_leg"/>
    <child link="RL_toe"/>
    <axis xyz="0.64279 0 0.76604"/>
  </joint>
  <link name="FR_hip">
    <inertial>
      <origin rpy="0 0 0" xyz="0.018798 -0.0032741 0.00039709"/>
      <mass value="0.032069"/>
      <inertia ixx="5.9912E-06" ixy="-4.4714E-07" ixz="1.8534E-10" iyy="2.954E-06" iyz="-6.2909E-08" izz="5.7295E-06"/>
    </inertial>
    <visual>
      <origin rpy="0 0 0" xyz="0 0 0"/>
      <geometry>
        <mesh filename="package://pupperv2_description/meshes/FR_hip.STL"/>
      </geometry>
      <material name="">
        <color rgba="0.75294 0.75294 0.75294 1"/>
      </material>
    </visual>
    <collision>
      <origin rpy="0 0 0" xyz="0 0 0"/>
      <geometry>
        <mesh filename="package://pupperv2_description/meshes/FR_hip.STL"/>
      </geometry>
    </collision>
  </link>
  <joint name="base_link_FR_hip" type="revolute">
    <origin rpy="0 0 0" xyz="0.035885 -0.0474 0.00461"/>
    <parent link="base_link"/>
    <child link="FR_hip"/>
    <axis xyz="1 0 0"/>
    <limit effort="100" lower="-0.7854" upper="0.7854" velocity="2.5"/>
  </joint>
  <link name="FR_upper_leg">
    <inertial>
      <origin rpy="0 0 0" xyz="-0.00011578 -0.025203 -0.048064"/>
      <mass value="0.054665"/>
      <inertia ixx="2.4386E-05" ixy="1.682E-10" ixz="-2.6061E-07" iyy="2.3437E-05" iyz="-2.7137E-07" izz="6.6679E-06"/>
    </inertial>
    <visual>
      <origin rpy="0 0 0" xyz="0 0 0"/>
      <geometry>
        <mesh filename="package://pupperv2_description/meshes/FR_upper_leg.STL"/>
      </geometry>
      <material name="">
        <color rgba="0.75294 0.75294 0.75294 1"/>
      </material>
    </visual>
    <collision>
      <origin rpy="0 0 0" xyz="0 0 0"/>
      <geometry>
        <mesh filename="package://pupperv2_description/meshes/FR_upper_leg.STL"/>
      </geometry>
    </collision>
  </link>
  <joint name="FR_hip_FR_upper_leg" type="revolute">
    <origin rpy="0 0 0" xyz="0.015252 -0.02535 0"/>
    <parent link="FR_hip"/>
    <child link="FR_upper_leg"/>
    <axis xyz="0 1 0"/>
    <limit effort="100" lower="-4.4506" upper="1.309" velocity="2.5"/>
  </joint>
  <link name="FR_lower_leg">
    <inertial>
      <origin rpy="0 0 0" xyz="0.00028375 -0.0039771 -0.040393"/>
      <mass value="0.016741"/>
      <inertia ixx="1.8313E-05" ixy="1.9858E-08" ixz="2.3431E-07" iyy="1.854E-05" iyz="-6.769E-07" izz="5.5333E-07"/>
    </inertial>
    <visual>
      <origin rpy="0 0 0" xyz="0 0 0"/>
      <geometry>
        <mesh filename="package://pupperv2_description/meshes/FR_lower_leg.STL"/>
      </geometry>
      <material name="">
        <color rgba="0.75294 0.75294 0.75294 1"/>
      </material>
    </visual>
    <collision>
      <origin rpy="0 0 0" xyz="0 0 0"/>
      <geometry>
        <mesh filename="package://pupperv2_description/meshes/FR_lower_leg.STL"/>
      </geometry>
    </collision>
  </link>
  <joint name="FR_upper_leg_FR_lower_leg" type="revolute">
    <origin rpy="0 0 0" xyz="0 0 -0.08"/>
    <parent link="FR_upper_leg"/>
    <child link="FR_lower_leg"/>
    <axis xyz="0 1 0"/>
    <limit effort="100" lower="-2.8798" upper="2.8798" velocity="2.5"/>
  </joint>
  <link name="FR_toe">
    <inertial>
      <origin rpy="0 0 0" xyz="-0.002296 6.9389E-18 -0.0027362"/>
      <mass value="0.0018099"/>
      <inertia ixx="5.2131E-08" ixy="6.2047E-25" ixz="1.137E-08" iyy="4.259E-08" iyz="9.8352E-25" izz="5.6141E-08"/>
    </inertial>
    <visual>
      <origin rpy="0 0 0" xyz="0 0 0"/>
      <geometry>
        <mesh filename="package://pupperv2_description/meshes/FR_toe.STL"/>
      </geometry>
      <material name="">
        <color rgba="0.15294 0.15294 0.15294 1"/>
      </material>
    </visual>
    <collision>
      <origin rpy="0 0 0" xyz="0 0 0"/>
      <geometry>
        <mesh filename="package://pupperv2_description/meshes/FR_toe.STL"/>
      </geometry>
    </collision>
  </link>
  <joint name="FR_lower_leg_FR_toe" type="fixed">
    <origin rpy="0 0 0" xyz="0 -0.008325 -0.11"/>
    <parent link="FR_lower_leg"/>
    <child link="FR_toe"/>
    <axis xyz="0.64279 0 0.76604"/>
  </joint>
  <link name="RR_hip">
    <inertial>
      <origin rpy="0 0 0" xyz="-0.022479 -0.0032741 0.00039709"/>
      <mass value="0.032069"/>
      <inertia ixx="5.9912E-06" ixy="-4.4714E-07" ixz="1.8534E-10" iyy="2.954E-06" iyz="-6.2909E-08" izz="5.7295E-06"/>
    </inertial>
    <visual>
      <origin rpy="0 0 0" xyz="0 0 0"/>
      <geometry>
        <mesh filename="package://pupperv2_description/meshes/RR_hip.STL"/>
      </geometry>
      <material name="">
        <color rgba="0.75294 0.75294 0.75294 1"/>
      </material>
    </visual>
    <collision>
      <origin rpy="0 0 0" xyz="0 0 0"/>
      <geometry>
        <mesh filename="package://pupperv2_description/meshes/RR_hip.STL"/>
      </geometry>
    </collision>
  </link>
  <joint name="base_link_RR_hip" type="revolute">
    <origin rpy="0 0 0" xyz="-0.12284 -0.0474 0.00461"/>
    <parent link="base_link"/>
    <child link="RR_hip"/>
    <axis xyz="1 0 0"/>
    <limit effort="100" lower="-0.7854" upper="0.7854" velocity="2.5"/>
  </joint>
  <link name="RR_upper_leg">
    <inertial>
      <origin rpy="0 0 0" xyz="-0.00011578 -0.025203 -0.048064"/>
      <mass value="0.054665"/>
      <inertia ixx="2.4386E-05" ixy="1.682E-10" ixz="-2.6061E-07" iyy="2.3437E-05" iyz="-2.7137E-07" izz="6.6679E-06"/>
    </inertial>
    <visual>
      <origin rpy="0 0 0" xyz="0 0 0"/>
      <geometry>
        <mesh filename="package://pupperv2_description/meshes/RR_upper_leg.STL"/>
      </geometry>
      <material name="">
        <color rgba="0.75294 0.75294 0.75294 1"/>
      </material>
    </visual>
    <collision>
      <origin rpy="0 0 0" xyz="0 0 0"/>
      <geometry>
        <mesh filename="package://pupperv2_description/meshes/RR_upper_leg.STL"/>
      </geometry>
    </collision>
  </link>
  <joint name="RR_hip_RR_upper_leg" type="revolute">
    <origin rpy="0 0 0" xyz="-0.026025 -0.02535 0"/>
    <parent link="RR_hip"/>
    <child link="RR_upper_leg"/>
    <axis xyz="0 1 0"/>
    <limit effort="100" lower="-4.4506" upper="1.309" velocity="2.5"/>
  </joint>
  <link name="RR_lower_leg">
    <inertial>
      <origin rpy="0 0 0" xyz="0.00028375 -0.0039771 -0.040393"/>
      <mass value="0.016741"/>
      <inertia ixx="1.8313E-05" ixy="1.9858E-08" ixz="2.3431E-07" iyy="1.854E-05" iyz="-6.769E-07" izz="5.5333E-07"/>
    </inertial>
    <visual>
      <origin rpy="0 0 0" xyz="0 0 0"/>
      <geometry>
        <mesh filename="package://pupperv2_description/meshes/RR_lower_leg.STL"/>
      </geometry>
      <material name="">
        <color rgba="0.75294 0.75294 0.75294 1"/>
      </material>
    </visual>
    <collision>
      <origin rpy="0 0 0" xyz="0 0 0"/>
      <geometry>
        <mesh filename="package://pupperv2_description/meshes/RR_lower_leg.STL"/>
      </geometry>
    </collision>
  </link>
  <joint name="RR_upper_leg_RR_lower_leg" type="revolute">
    <origin rpy="0 0 0" xyz="0 0 -0.08"/>
    <parent link="RR_upper_leg"/>
    <child link="RR_lower_leg"/>
    <axis xyz="0 1 0"/>
    <limit effort="100" lower="-2.8798" upper="2.8798" velocity="2.5"/>
  </joint>
  <link name="RR_toe">
    <inertial>
      <origin rpy="0 0 0" xyz="-0.002296 0 -0.0027362"/>
      <mass value="0.0018099"/>
      <inertia ixx="5.2131E-08" ixy="6.6018E-25" ixz="1.137E-08" iyy="4.259E-08" iyz="2.4451E-24" izz="5.6141E-08"/>
    </inertial>
    <visual>
      <origin rpy="0 0 0" xyz="0 0 0"/>
      <geometry>
        <mesh filename="package://pupperv2_description/meshes/RR_toe.STL"/>
      </geometry>
      <material name="">
        <color rgba="0.15294 0.15294 0.15294 1"/>
      </material>
    </visual>
    <collision>
      <origin rpy="0 0 0" xyz="0 0 0"/>
      <geometry>
        <mesh filename="package://pupperv2_description/meshes/RR_toe.STL"/>
      </geometry>
    </collision>
  </link>
  <joint name="RR_lower_leg_RR_toe" type="fixed">
    <origin rpy="0 0 0" xyz="0 -0.008325 -0.11"/>
    <parent link="RR_lower_leg"/>
    <child link="RR_toe"/>
    <axis xyz="0 0 0"/>
  </joint>
  <transmission name="base_link_FL_hip_trans">
    <type>transmission_interface/SimpleTransmission</type>
    <joint name="base_link_FL_hip">
      <hardwareInterface>hardware_interface/EffortJointInterface</hardwareInterface>
    </joint>
    <actuator name="base_link_FL_hip_motor">
      <hardwareInterface>hardware_interface/EffortJointInterfacce</hardwareInterface>
      <mechanicalReduction>1</mechanicalReduction>
    </actuator>
  </transmission>
  <transmission name="FL_hip_FL_upper_leg_trans">
    <type>transmission_interface/SimpleTransmission</type>
    <joint name="FL_hip_FL_upper_leg">
      <hardwareInterface>hardware_interface/EffortJointInterface</hardwareInterface>
    </joint>
    <actuator name="FL_hip_FL_upper_leg_motor">
      <hardwareInterface>hardware_interface/EffortJointInterfacce</hardwareInterface>
      <mechanicalReduction>1</mechanicalReduction>
    </actuator>
  </transmission>
  <transmission name="FL_upper_leg_FL_lower_leg_trans">
    <type>transmission_interface/SimpleTransmission</type>
    <joint name="FL_upper_leg_FL_lower_leg">
      <hardwareInterface>hardware_interface/EffortJointInterface</hardwareInterface>
    </joint>
    <actuator name="FL_upper_leg_FL_lower_leg_motor">
      <hardwareInterface>hardware_interface/EffortJointInterfacce</hardwareInterface>
      <mechanicalReduction>1</mechanicalReduction>
    </actuator>
  </transmission>
  <transmission name="base_link_FR_hip_trans">
    <type>transmission_interface/SimpleTransmission</type>
    <joint name="base_link_FR_hip">
      <hardwareInterface>hardware_interface/EffortJointInterface</hardwareInterface>
    </joint>
    <actuator name="base_link_FR_hip_motor">
      <hardwareInterface>hardware_interface/EffortJointInterfacce</hardwareInterface>
      <mechanicalReduction>1</mechanicalReduction>
    </actuator>
  </transmission>
  <transmission name="FR_hip_FR_upper_leg_trans">
    <type>transmission_interface/SimpleTransmission</type>
    <joint name="FR_hip_FR_upper_leg">
      <hardwareInterface>hardware_interface/EffortJointInterface</hardwareInterface>
    </joint>
    <actuator name="FR_hip_FR_upper_leg_motor">
      <hardwareInterface>hardware_interface/EffortJointInterfacce</hardwareInterface>
      <mechanicalReduction>1</mechanicalReduction>
    </actuator>
  </transmission>
  <transmission name="FR_upper_leg_FR_lower_leg_trans">
    <type>transmission_interface/SimpleTransmission</type>
    <joint name="FR_upper_leg_FR_lower_leg">
      <hardwareInterface>hardware_interface/EffortJointInterface</hardwareInterface>
    </joint>
    <actuator name="FR_upper_leg_FR_lower_leg_motor">
      <hardwareInterface>hardware_interface/EffortJointInterfacce</hardwareInterface>
      <mechanicalReduction>1</mechanicalReduction>
    </actuator>
  </transmission>
  <transmission name="base_link_RL_hip_trans">
    <type>transmission_interface/SimpleTransmission</type>
    <joint name="base_link_RL_hip">
      <hardwareInterface>hardware_interface/EffortJointInterface</hardwareInterface>
    </joint>
    <actuator name="base_link_RL_hip_motor">
      <hardwareInterface>hardware_interface/EffortJointInterfacce</hardwareInterface>
      <mechanicalReduction>1</mechanicalReduction>
    </actuator>
  </transmission>
  <transmission name="RL_hip_RL_upper_leg_trans">
    <type>transmission_interface/SimpleTransmission</type>
    <joint name="RL_hip_RL_upper_leg">
      <hardwareInterface>hardware_interface/EffortJointInterface</hardwareInterface>
    </joint>
    <actuator name="RL_hip_RL_upper_leg_motor">
      <hardwareInterface>hardware_interface/EffortJointInterfacce</hardwareInterface>
      <mechanicalReduction>1</mechanicalReduction>
    </actuator>
  </transmission>
  <transmission name="RL_upper_leg_RL_lower_leg_trans">
    <type>transmission_interface/SimpleTransmission</type>
    <joint name="RL_upper_leg_RL_lower_leg">
      <hardwareInterface>hardware_interface/EffortJointInterface</hardwareInterface>
    </joint>
    <actuator name="RL_upper_leg_RL_lower_leg_motor">
      <hardwareInterface>hardware_interface/EffortJointInterfacce</hardwareInterface>
      <mechanicalReduction>1</mechanicalReduction>
    </actuator>
  </transmission>
  <transmission name="base_link_RR_hip_trans">
    <type>transmission_interface/SimpleTransmission</type>
    <joint name="base_link_RR_hip">
      <hardwareInterface>hardware_interface/EffortJointInterface</hardwareInterface>
    </joint>
    <actuator name="base_link_RR_hip_motor">
      <hardwareInterface>hardware_interface/EffortJointInterfacce</hardwareInterface>
      <mechanicalReduction>1</mechanicalReduction>
    </actuator>
  </transmission>
  <transmission name="RR_hip_RR_upper_leg_trans">
    <type>transmission_interface/SimpleTransmission</type>
    <joint name="RR_hip_RR_upper_leg">
      <hardwareInterface>hardware_interface/EffortJointInterface</hardwareInterface>
    </joint>
    <actuator name="RR_hip_RR_upper_leg_motor">
      <hardwareInterface>hardware_interface/EffortJointInterfacce</hardwareInterface>
      <mechanicalReduction>1</mechanicalReduction>
    </actuator>
  </transmission>
  <transmission name="RR_upper_leg_RR_lower_leg_trans">
    <type>transmission_interface/SimpleTransmission</type>
    <joint name="RR_upper_leg_RR_lower_leg">
      <hardwareInterface>hardware_interface/EffortJointInterface</hardwareInterface>
    </joint>
    <actuator name="RR_upper_leg_RR_lower_leg_motor">
      <hardwareInterface>hardware_interface/EffortJointInterfacce</hardwareInterface>
      <mechanicalReduction>1</mechanicalReduction>
    </actuator>
  </transmission>
  <gazebo reference="FL_toe">
    <kp>1000000</kp>
    <kd>1.0</kd>
    <mu1>0.8</mu1>
    <mu2>0.8</mu2>
    <maxVel>0.0</maxVel>
    <minDepth>0.001</minDepth>
  </gazebo>
  <gazebo reference="RL_toe">
    <kp>1000000</kp>
    <kd>1.0</kd>
    <mu1>0.8</mu1>
    <mu2>0.8</mu2>
    <maxVel>0.0</maxVel>
    <minDepth>0.001</minDepth>
  </gazebo>
  <gazebo reference="FR_toe">
    <kp>1000000</kp>
    <kd>1.0</kd>
    <mu1>0.8</mu1>
    <mu2>0.8</mu2>
    <maxVel>0.0</maxVel>
    <minDepth>0.001</minDepth>
  </gazebo>
  <gazebo reference="RR_toe">
    <kp>1000000</kp>
    <kd>1.0</kd>
    <mu1>0.8</mu1>
    <mu2>0.8</mu2>
    <maxVel>0.0</maxVel>
    <minDepth>0.001</minDepth>
  </gazebo>
</robot>

