<?xml version="1.0" encoding="utf-8"?>
<!-- =================================================================================== -->
<!-- |    This document was autogenerated by xacro from xacro/spirit_gazebo_tail.urdf.xacro | -->
<!-- |    EDITING THIS FILE BY HAND IS NOT RECOMMENDED                                 | -->
<!-- =================================================================================== -->
<!-- 
MIT License (modified)

Copyright (c) 2020 Ghost Robotics
Authors:
Avik De <avik@ghostrobotics.io>
Tom Jacobs <tom.jacobs@ghostrobotics.io>

Permission is hereby granted, free of charge, to any person obtaining a copy
of this **file** (the "Software"), to deal
in the Software without restriction, including without limitation the rights
to use, copy, modify, merge, publish, distribute, sublicense, and/or sell
copies of the Software, and to permit persons to whom the Software is
furnished to do so, subject to the following conditions:

The above copyright notice and this permission notice shall be included in all
copies or substantial portions of the Software.

THE SOFTWARE IS PROVIDED "AS IS", WITHOUT WARRANTY OF ANY KIND, EXPRESS OR
IMPLIED, INCLUDING BUT NOT LIMITED TO THE WARRANTIES OF MERCHANTABILITY,
FITNESS FOR A PARTICULAR PURPOSE AND NONINFRINGEMENT. IN NO EVENT SHALL THE
AUTHORS OR COPYRIGHT HOLDERS BE LIABLE FOR ANY CLAIM, DAMAGES OR OTHER
LIABILITY, WHETHER IN AN ACTION OF CONTRACT, TORT OR OTHERWISE, ARISING FROM,
OUT OF OR IN CONNECTION WITH THE SOFTWARE OR THE USE OR OTHER DEALINGS IN THE
SOFTWARE. 
-->
<robot name="spirit">
  <!-- Plugins -->
  <gazebo>
    <plugin filename="libgazebo_ros_control.so" name="gazebo_ros_control">
      <robotNamespace>/spirit</robotNamespace>
      <controlPeriod>0.002</controlPeriod>
    </plugin>
    <plugin filename="libground_truth_estimator.so" name="ground_truth_estimator">
      <updateRateHz>500.0</updateRateHz>
    </plugin>
  </gazebo>
  <!--link name="body_dummy">
		<inertial>
			<mass value="${bodyMass}" />
			<inertia ixx="0.05" ixy="0" ixz="0" iyy="0.1" iyz="0" izz="0.1" />
		</inertial>
	</link>
	<joint name="dummy_joint" type="fixed">
		<parent link="body_dummy" />
		<child link="body" />
	</joint-->
  <!-- Body -->
  <link name="body">
    <visual>
      <origin rpy="0 0 0" xyz="0 0 0" />
      <geometry>
        <box size="0.335 0.24 0.104" />
      </geometry>
      <material name="darkgray" />
    </visual>
    <inertial>
      <mass value="7.388" />
      <!--<mass value="${bodyMass}" /> -->
      <!-- Uniform box -->
      <!-- <inertia ixx="1/12*${bodyMass}*(${bodyWidth}*${bodyWidth} + ${bodyHeight}*${bodyHeight})"  ixy="0"  ixz="0" iyy="1/12*${bodyMass}*(${bodyLength}*${bodyLength} + ${bodyHeight}*${bodyHeight})" iyz="0" izz="1/12*${bodyMass}*(${bodyLength}*${bodyLength} + ${bodyWidth}*${bodyWidth})"/> -->
      <inertia ixx="0.0642434782" ixy="0" ixz="0" iyy="0.1284869565" iyz="0" izz="0.1284869565" />
      <!--<inertia ixx="0.05" ixy="0" ixz="0" iyy="0.1" iyz="0" izz="0.1" />-->
    </inertial>
    <!-- Just copy geometry for collision -->
    <collision>
      <origin rpy="0 0 0" xyz="0 0 0" />
      <geometry>
        <box size="0.335 0.24 0.104" />
      </geometry>
    </collision>
  </link>
  <gazebo reference="body">
    <material>Gazebo/Black</material>
  </gazebo>
  <!-- Hip motor -->
  <link name="hip0">
    <visual>
      <origin rpy="1.5707963268 0 0" xyz="0 0.028 0" />
      <geometry>
        <cylinder length="0.08" radius="0.055" />
      </geometry>
    </visual>
    <collision>
      <origin rpy="1.5707963268 0 0" xyz="0 0.028 0" />
      <geometry>
        <cylinder length="0.08" radius="0.055" />
      </geometry>
    </collision>
    <inertial>
      <origin rpy="1.5707963268 0 0" xyz="0 0.028 0" />
      <mass value="0.575" />
      <inertia ixx="0.000741510416667" ixy="0" ixz="0" iyy="0.000741510416667" iyz="0" izz="0.0008696875" />
      <!-- Okay for now... forgot when cylinder is formed what direction is x pointing in -->
      <!--inertia ixx="0.00066963541" ixy="0" ixz="0" iyy="0.00066963541" iyz="0" izz="0.0008696875" /-->
    </inertial>
  </link>
  <gazebo reference="hip0">
    <material>Gazebo/Grey</material>
  </gazebo>
  <!-- Abduction joint. Joint names are: 8 9 10 11 -->
  <joint name="8" type="revolute">
    <parent link="body" />
    <child link="hip0" />
    <axis xyz="1 0 0" />
    <origin xyz="0.2263 0.07 0" />
    <limit effort="21" lower="-0.707" upper="0.707" velocity="37.7" />
    <dynamics damping="0.0" friction="0.0" />
  </joint>
  <!-- Transmission elements required for Gazebo -->
  <transmission name="transmission_8">
    <type>transmission_interface/SimpleTransmission</type>
    <joint name="8">
      <hardwareInterface>hardware_interface/EffortJointInterface</hardwareInterface>
    </joint>
    <actuator name="motor_8">
      <hardwareInterface>EffortJointInterface</hardwareInterface>
      <mechanicalReduction>1</mechanicalReduction>
    </actuator>
  </transmission>
  <!-- Upper leg -->
  <link name="upper0">
    <visual>
      <origin rpy="0 0 0" xyz="-0.103 -0.022 0" />
      <geometry>
        <box size="0.206 0.022 0.055" />
      </geometry>
      <material name="silver" />
    </visual>
    <collision>
      <origin rpy="0 0 0" xyz="-0.103 -0.022 0" />
      <geometry>
        <box size="0.206 0.022 0.055" />
      </geometry>
    </collision>
    <inertial>
      <origin rpy="0 0 0" xyz="-0.103 -0.022 0" />
      <mass value="0.792" />
      <!--<inertia ixx="${upperLegIxx}" ixy="0" ixz="0" iyy="${upperLegIyy}" iyz="0" izz="${upperLegIzz}" /> -->
      <inertia ixx="0.000231594" ixy="0" ixz="0" iyy="0.003000426" iyz="0" izz="0.00283272" />
    </inertial>
  </link>
  <gazebo reference="upper0">
    <self_collide>0</self_collide>
    <material>Gazebo/DarkGrey</material>
  </gazebo>
  <!-- Hip joint. (Motor to upper leg). Joint names are: 0 2 4 6 -->
  <joint name="0" type="revolute">
    <parent link="hip0" />
    <child link="upper0" />
    <axis xyz="0 -1 0" />
    <origin xyz="0 0.10098 0" />
    <!--  rpy="0 -0.3 0" -->
    <limit effort="21" lower="-1.57" upper="3.14" velocity="37.7" />
    <dynamics damping="0.0" friction="0.0" />
  </joint>
  <!-- Transmission elements required for Gazebo -->
  <transmission name="transmission_0">
    <type>transmission_interface/SimpleTransmission</type>
    <joint name="0">
      <hardwareInterface>hardware_interface/EffortJointInterface</hardwareInterface>
    </joint>
    <actuator name="motor_0">
      <hardwareInterface>EffortJointInterface</hardwareInterface>
      <mechanicalReduction>1</mechanicalReduction>
    </actuator>
  </transmission>
  <!-- Lower leg -->
  <link name="lower0">
    <self_collide>0</self_collide>
    <visual>
      <origin rpy="0 1.5707963268 0" xyz="0.103 0 0" />
      <geometry>
        <cylinder length="0.206" radius="0.013" />
      </geometry>
      <material name="darkgray" />
    </visual>
    <collision>
      <origin rpy="0 1.5707963268 0" xyz="0.103 0 0" />
      <geometry>
        <cylinder length="0.206" radius="0.013" />
      </geometry>
    </collision>
    <inertial>
      <origin rpy="0 0 0" xyz="0.103 0 0" />
      <mass value="0.075" />
      <!--inertia ixx="${lowerLegIxx}" ixy="0" ixz="0" iyy="${lowerLegIyy}" iyz="0" izz="${lowerLegIzz}" /-->
      <inertia ixx="2.193125e-05" ixy="0" ixz="0" iyy="0.00028413125" iyz="0" izz="0.00026825" />
    </inertial>
  </link>
  <gazebo reference="lower0">
    <material>Gazebo/Grey</material>
  </gazebo>
  <!-- Knee joint. Joint names are: 1 3 5 7 -->
  <joint name="1" type="revolute">
    <parent link="upper0" />
    <child link="lower0" />
    <axis xyz="0 1 0" />
    <origin xyz="-0.206 0 0" />
    <!--rpy="0 0.5 0"-->
    <!--<limit effort="${jointEffortLimit}" velocity="${jointSpeedLimit}" lower="0" upper="${pi}" />-->
    <limit effort="32" lower="-6.28" upper="6.28" velocity="25.1" />
    <dynamics damping="0.0" friction="0.0" />
  </joint>
  <!-- Transmission elements required for Gazebo -->
  <transmission name="transmission_1">
    <type>transmission_interface/SimpleTransmission</type>
    <joint name="1">
      <hardwareInterface>hardware_interface/EffortJointInterface</hardwareInterface>
    </joint>
    <actuator name="motor_1">
      <hardwareInterface>EffortJointInterface</hardwareInterface>
      <mechanicalReduction>1</mechanicalReduction>
    </actuator>
  </transmission>
  <!-- Toe -->
  <link name="toe0">
    <contact>
      <friction_anchor />
      <stiffness value="30000.0" />
      <damping value="1000.0" />
      <spinning_friction value="0.3" />
      <lateral_friction value="50.0" />
    </contact>
    <visual>
      <origin rpy="0 0 0" xyz="0 0 0" />
      <geometry>
        <sphere radius="0.02" />
      </geometry>
      <material name="darkgray" />
    </visual>
    <collision>
      <origin rpy="0 0 0" xyz="0 0 0" />
      <geometry>
        <sphere radius="0.02" />
      </geometry>
    </collision>
    <inertial>
      <mass value="0.015" />
      <inertia ixx="0.000025" ixy="0" ixz="0" iyy="0.000025" iyz="0" izz="0.000025" />
      <!-- <inertia ixx="2/5*${toeMass}*${toeRadius}*${toeRadius}"  ixy="0"  ixz="0" iyy="2/5*${toeMass}*${toeRadius}*${toeRadius}" iyz="0" izz="2/5*${toeMass}*${toeRadius}*${toeRadius}" /> -->
    </inertial>
  </link>
  <gazebo reference="toe0">
    <self_collide>0</self_collide>
    <material>Gazebo/Black</material>
    <collision>
      <surface>
        <bounce>
          <restitution_coefficient>0</restitution_coefficient>
          <threshold>1e+06</threshold>
        </bounce>
        <friction>
          <torsional>
            <coefficient>0.3</coefficient>
          </torsional>
          <ode>
            <mu>100.0</mu>
            <mu2>50.0</mu2>
          </ode>
          <bullet>
            <rolling_friction>0.3</rolling_friction>
            <friction2>50.0</friction2>
          </bullet>
        </friction>
        <contact>
          <bullet>
            <kp>30000.0</kp>
            <kd>1000.0</kd>
          </bullet>
          <ode>
            <kp>30000.0</kp>
            <kd>1000.0</kd>
          </ode>
        </contact>
      </surface>
    </collision>
  </gazebo>
  <joint name="jtoe0" type="fixed">
    <parent link="lower0" />
    <child link="toe0" />
    <origin xyz="0.206 0 -0.0" />
    <dynamics damping="0.0" friction="0.0" />
  </joint>
  <!-- Hip motor -->
  <link name="hip1">
    <visual>
      <origin rpy="1.5707963268 0 0" xyz="0 0.028 0" />
      <geometry>
        <cylinder length="0.08" radius="0.055" />
      </geometry>
    </visual>
    <collision>
      <origin rpy="1.5707963268 0 0" xyz="0 0.028 0" />
      <geometry>
        <cylinder length="0.08" radius="0.055" />
      </geometry>
    </collision>
    <inertial>
      <origin rpy="1.5707963268 0 0" xyz="0 0.028 0" />
      <mass value="0.575" />
      <inertia ixx="0.000741510416667" ixy="0" ixz="0" iyy="0.000741510416667" iyz="0" izz="0.0008696875" />
      <!-- Okay for now... forgot when cylinder is formed what direction is x pointing in -->
      <!--inertia ixx="0.00066963541" ixy="0" ixz="0" iyy="0.00066963541" iyz="0" izz="0.0008696875" /-->
    </inertial>
  </link>
  <gazebo reference="hip1">
    <material>Gazebo/Grey</material>
  </gazebo>
  <!-- Abduction joint. Joint names are: 8 9 10 11 -->
  <joint name="9" type="revolute">
    <parent link="body" />
    <child link="hip1" />
    <axis xyz="1 0 0" />
    <origin xyz="-0.2263 0.07 0" />
    <limit effort="21" lower="-0.707" upper="0.707" velocity="37.7" />
    <dynamics damping="0.0" friction="0.0" />
  </joint>
  <!-- Transmission elements required for Gazebo -->
  <transmission name="transmission_9">
    <type>transmission_interface/SimpleTransmission</type>
    <joint name="9">
      <hardwareInterface>hardware_interface/EffortJointInterface</hardwareInterface>
    </joint>
    <actuator name="motor_9">
      <hardwareInterface>EffortJointInterface</hardwareInterface>
      <mechanicalReduction>1</mechanicalReduction>
    </actuator>
  </transmission>
  <!-- Upper leg -->
  <link name="upper1">
    <visual>
      <origin rpy="0 0 0" xyz="-0.103 -0.022 0" />
      <geometry>
        <box size="0.206 0.022 0.055" />
      </geometry>
      <material name="silver" />
    </visual>
    <collision>
      <origin rpy="0 0 0" xyz="-0.103 -0.022 0" />
      <geometry>
        <box size="0.206 0.022 0.055" />
      </geometry>
    </collision>
    <inertial>
      <origin rpy="0 0 0" xyz="-0.103 -0.022 0" />
      <mass value="0.792" />
      <!--<inertia ixx="${upperLegIxx}" ixy="0" ixz="0" iyy="${upperLegIyy}" iyz="0" izz="${upperLegIzz}" /> -->
      <inertia ixx="0.000231594" ixy="0" ixz="0" iyy="0.003000426" iyz="0" izz="0.00283272" />
    </inertial>
  </link>
  <gazebo reference="upper1">
    <self_collide>0</self_collide>
    <material>Gazebo/DarkGrey</material>
  </gazebo>
  <!-- Hip joint. (Motor to upper leg). Joint names are: 0 2 4 6 -->
  <joint name="2" type="revolute">
    <parent link="hip1" />
    <child link="upper1" />
    <axis xyz="0 -1 0" />
    <origin xyz="0 0.10098 0" />
    <!--  rpy="0 -0.3 0" -->
    <limit effort="21" lower="-1.57" upper="3.14" velocity="37.7" />
    <dynamics damping="0.0" friction="0.0" />
  </joint>
  <!-- Transmission elements required for Gazebo -->
  <transmission name="transmission_2">
    <type>transmission_interface/SimpleTransmission</type>
    <joint name="2">
      <hardwareInterface>hardware_interface/EffortJointInterface</hardwareInterface>
    </joint>
    <actuator name="motor_2">
      <hardwareInterface>EffortJointInterface</hardwareInterface>
      <mechanicalReduction>1</mechanicalReduction>
    </actuator>
  </transmission>
  <!-- Lower leg -->
  <link name="lower1">
    <self_collide>0</self_collide>
    <visual>
      <origin rpy="0 1.5707963268 0" xyz="0.103 0 0" />
      <geometry>
        <cylinder length="0.206" radius="0.013" />
      </geometry>
      <material name="darkgray" />
    </visual>
    <collision>
      <origin rpy="0 1.5707963268 0" xyz="0.103 0 0" />
      <geometry>
        <cylinder length="0.206" radius="0.013" />
      </geometry>
    </collision>
    <inertial>
      <origin rpy="0 0 0" xyz="0.103 0 0" />
      <mass value="0.075" />
      <!--inertia ixx="${lowerLegIxx}" ixy="0" ixz="0" iyy="${lowerLegIyy}" iyz="0" izz="${lowerLegIzz}" /-->
      <inertia ixx="2.193125e-05" ixy="0" ixz="0" iyy="0.00028413125" iyz="0" izz="0.00026825" />
    </inertial>
  </link>
  <gazebo reference="lower1">
    <material>Gazebo/Grey</material>
  </gazebo>
  <!-- Knee joint. Joint names are: 1 3 5 7 -->
  <joint name="3" type="revolute">
    <parent link="upper1" />
    <child link="lower1" />
    <axis xyz="0 1 0" />
    <origin xyz="-0.206 0 0" />
    <!--rpy="0 0.5 0"-->
    <!--<limit effort="${jointEffortLimit}" velocity="${jointSpeedLimit}" lower="0" upper="${pi}" />-->
    <limit effort="32" lower="-6.28" upper="6.28" velocity="25.1" />
    <dynamics damping="0.0" friction="0.0" />
  </joint>
  <!-- Transmission elements required for Gazebo -->
  <transmission name="transmission_3">
    <type>transmission_interface/SimpleTransmission</type>
    <joint name="3">
      <hardwareInterface>hardware_interface/EffortJointInterface</hardwareInterface>
    </joint>
    <actuator name="motor_3">
      <hardwareInterface>EffortJointInterface</hardwareInterface>
      <mechanicalReduction>1</mechanicalReduction>
    </actuator>
  </transmission>
  <!-- Toe -->
  <link name="toe1">
    <contact>
      <friction_anchor />
      <stiffness value="30000.0" />
      <damping value="1000.0" />
      <spinning_friction value="0.3" />
      <lateral_friction value="50.0" />
    </contact>
    <visual>
      <origin rpy="0 0 0" xyz="0 0 0" />
      <geometry>
        <sphere radius="0.02" />
      </geometry>
      <material name="darkgray" />
    </visual>
    <collision>
      <origin rpy="0 0 0" xyz="0 0 0" />
      <geometry>
        <sphere radius="0.02" />
      </geometry>
    </collision>
    <inertial>
      <mass value="0.015" />
      <inertia ixx="0.000025" ixy="0" ixz="0" iyy="0.000025" iyz="0" izz="0.000025" />
      <!-- <inertia ixx="2/5*${toeMass}*${toeRadius}*${toeRadius}"  ixy="0"  ixz="0" iyy="2/5*${toeMass}*${toeRadius}*${toeRadius}" iyz="0" izz="2/5*${toeMass}*${toeRadius}*${toeRadius}" /> -->
    </inertial>
  </link>
  <gazebo reference="toe1">
    <self_collide>0</self_collide>
    <material>Gazebo/Black</material>
    <collision>
      <surface>
        <bounce>
          <restitution_coefficient>0</restitution_coefficient>
          <threshold>1e+06</threshold>
        </bounce>
        <friction>
          <torsional>
            <coefficient>0.3</coefficient>
          </torsional>
          <ode>
            <mu>100.0</mu>
            <mu2>50.0</mu2>
          </ode>
          <bullet>
            <rolling_friction>0.3</rolling_friction>
            <friction2>50.0</friction2>
          </bullet>
        </friction>
        <contact>
          <bullet>
            <kp>30000.0</kp>
            <kd>1000.0</kd>
          </bullet>
          <ode>
            <kp>30000.0</kp>
            <kd>1000.0</kd>
          </ode>
        </contact>
      </surface>
    </collision>
  </gazebo>
  <joint name="jtoe1" type="fixed">
    <parent link="lower1" />
    <child link="toe1" />
    <origin xyz="0.206 0 -0.0" />
    <dynamics damping="0.0" friction="0.0" />
  </joint>
  <!-- Hip motor -->
  <link name="hip2">
    <visual>
      <origin rpy="1.5707963268 0 0" xyz="0 -0.028 0" />
      <geometry>
        <cylinder length="0.08" radius="0.055" />
      </geometry>
    </visual>
    <collision>
      <origin rpy="1.5707963268 0 0" xyz="0 -0.028 0" />
      <geometry>
        <cylinder length="0.08" radius="0.055" />
      </geometry>
    </collision>
    <inertial>
      <origin rpy="1.5707963268 0 0" xyz="0 -0.028 0" />
      <mass value="0.575" />
      <inertia ixx="0.000741510416667" ixy="0" ixz="0" iyy="0.000741510416667" iyz="0" izz="0.0008696875" />
      <!-- Okay for now... forgot when cylinder is formed what direction is x pointing in -->
      <!--inertia ixx="0.00066963541" ixy="0" ixz="0" iyy="0.00066963541" iyz="0" izz="0.0008696875" /-->
    </inertial>
  </link>
  <gazebo reference="hip2">
    <material>Gazebo/Grey</material>
  </gazebo>
  <!-- Abduction joint. Joint names are: 8 9 10 11 -->
  <joint name="10" type="revolute">
    <parent link="body" />
    <child link="hip2" />
    <axis xyz="1 0 0" />
    <origin xyz="0.2263 -0.07 0" />
    <limit effort="21" lower="-0.707" upper="0.707" velocity="37.7" />
    <dynamics damping="0.0" friction="0.0" />
  </joint>
  <!-- Transmission elements required for Gazebo -->
  <transmission name="transmission_10">
    <type>transmission_interface/SimpleTransmission</type>
    <joint name="10">
      <hardwareInterface>hardware_interface/EffortJointInterface</hardwareInterface>
    </joint>
    <actuator name="motor_10">
      <hardwareInterface>EffortJointInterface</hardwareInterface>
      <mechanicalReduction>1</mechanicalReduction>
    </actuator>
  </transmission>
  <!-- Upper leg -->
  <link name="upper2">
    <visual>
      <origin rpy="0 0 0" xyz="-0.103 0.022 0" />
      <geometry>
        <box size="0.206 0.022 0.055" />
      </geometry>
      <material name="silver" />
    </visual>
    <collision>
      <origin rpy="0 0 0" xyz="-0.103 0.022 0" />
      <geometry>
        <box size="0.206 0.022 0.055" />
      </geometry>
    </collision>
    <inertial>
      <origin rpy="0 0 0" xyz="-0.103 0.022 0" />
      <mass value="0.792" />
      <!--<inertia ixx="${upperLegIxx}" ixy="0" ixz="0" iyy="${upperLegIyy}" iyz="0" izz="${upperLegIzz}" /> -->
      <inertia ixx="0.000231594" ixy="0" ixz="0" iyy="0.003000426" iyz="0" izz="0.00283272" />
    </inertial>
  </link>
  <gazebo reference="upper2">
    <self_collide>0</self_collide>
    <material>Gazebo/DarkGrey</material>
  </gazebo>
  <!-- Hip joint. (Motor to upper leg). Joint names are: 0 2 4 6 -->
  <joint name="4" type="revolute">
    <parent link="hip2" />
    <child link="upper2" />
    <axis xyz="0 -1 0" />
    <origin xyz="0 -0.10098 0" />
    <!--  rpy="0 -0.3 0" -->
    <limit effort="21" lower="-1.57" upper="3.14" velocity="37.7" />
    <dynamics damping="0.0" friction="0.0" />
  </joint>
  <!-- Transmission elements required for Gazebo -->
  <transmission name="transmission_4">
    <type>transmission_interface/SimpleTransmission</type>
    <joint name="4">
      <hardwareInterface>hardware_interface/EffortJointInterface</hardwareInterface>
    </joint>
    <actuator name="motor_4">
      <hardwareInterface>EffortJointInterface</hardwareInterface>
      <mechanicalReduction>1</mechanicalReduction>
    </actuator>
  </transmission>
  <!-- Lower leg -->
  <link name="lower2">
    <self_collide>0</self_collide>
    <visual>
      <origin rpy="0 1.5707963268 0" xyz="0.103 0 0" />
      <geometry>
        <cylinder length="0.206" radius="0.013" />
      </geometry>
      <material name="darkgray" />
    </visual>
    <collision>
      <origin rpy="0 1.5707963268 0" xyz="0.103 0 0" />
      <geometry>
        <cylinder length="0.206" radius="0.013" />
      </geometry>
    </collision>
    <inertial>
      <origin rpy="0 0 0" xyz="0.103 0 0" />
      <mass value="0.075" />
      <!--inertia ixx="${lowerLegIxx}" ixy="0" ixz="0" iyy="${lowerLegIyy}" iyz="0" izz="${lowerLegIzz}" /-->
      <inertia ixx="2.193125e-05" ixy="0" ixz="0" iyy="0.00028413125" iyz="0" izz="0.00026825" />
    </inertial>
  </link>
  <gazebo reference="lower2">
    <material>Gazebo/Grey</material>
  </gazebo>
  <!-- Knee joint. Joint names are: 1 3 5 7 -->
  <joint name="5" type="revolute">
    <parent link="upper2" />
    <child link="lower2" />
    <axis xyz="0 1 0" />
    <origin xyz="-0.206 0 0" />
    <!--rpy="0 0.5 0"-->
    <!--<limit effort="${jointEffortLimit}" velocity="${jointSpeedLimit}" lower="0" upper="${pi}" />-->
    <limit effort="32" lower="-6.28" upper="6.28" velocity="25.1" />
    <dynamics damping="0.0" friction="0.0" />
  </joint>
  <!-- Transmission elements required for Gazebo -->
  <transmission name="transmission_5">
    <type>transmission_interface/SimpleTransmission</type>
    <joint name="5">
      <hardwareInterface>hardware_interface/EffortJointInterface</hardwareInterface>
    </joint>
    <actuator name="motor_5">
      <hardwareInterface>EffortJointInterface</hardwareInterface>
      <mechanicalReduction>1</mechanicalReduction>
    </actuator>
  </transmission>
  <!-- Toe -->
  <link name="toe2">
    <contact>
      <friction_anchor />
      <stiffness value="30000.0" />
      <damping value="1000.0" />
      <spinning_friction value="0.3" />
      <lateral_friction value="50.0" />
    </contact>
    <visual>
      <origin rpy="0 0 0" xyz="0 0 0" />
      <geometry>
        <sphere radius="0.02" />
      </geometry>
      <material name="darkgray" />
    </visual>
    <collision>
      <origin rpy="0 0 0" xyz="0 0 0" />
      <geometry>
        <sphere radius="0.02" />
      </geometry>
    </collision>
    <inertial>
      <mass value="0.015" />
      <inertia ixx="0.000025" ixy="0" ixz="0" iyy="0.000025" iyz="0" izz="0.000025" />
      <!-- <inertia ixx="2/5*${toeMass}*${toeRadius}*${toeRadius}"  ixy="0"  ixz="0" iyy="2/5*${toeMass}*${toeRadius}*${toeRadius}" iyz="0" izz="2/5*${toeMass}*${toeRadius}*${toeRadius}" /> -->
    </inertial>
  </link>
  <gazebo reference="toe2">
    <self_collide>0</self_collide>
    <material>Gazebo/Black</material>
    <collision>
      <surface>
        <bounce>
          <restitution_coefficient>0</restitution_coefficient>
          <threshold>1e+06</threshold>
        </bounce>
        <friction>
          <torsional>
            <coefficient>0.3</coefficient>
          </torsional>
          <ode>
            <mu>100.0</mu>
            <mu2>50.0</mu2>
          </ode>
          <bullet>
            <rolling_friction>0.3</rolling_friction>
            <friction2>50.0</friction2>
          </bullet>
        </friction>
        <contact>
          <bullet>
            <kp>30000.0</kp>
            <kd>1000.0</kd>
          </bullet>
          <ode>
            <kp>30000.0</kp>
            <kd>1000.0</kd>
          </ode>
        </contact>
      </surface>
    </collision>
  </gazebo>
  <joint name="jtoe2" type="fixed">
    <parent link="lower2" />
    <child link="toe2" />
    <origin xyz="0.206 0 -0.0" />
    <dynamics damping="0.0" friction="0.0" />
  </joint>
  <!-- Hip motor -->
  <link name="hip3">
    <visual>
      <origin rpy="1.5707963268 0 0" xyz="0 -0.028 0" />
      <geometry>
        <cylinder length="0.08" radius="0.055" />
      </geometry>
    </visual>
    <collision>
      <origin rpy="1.5707963268 0 0" xyz="0 -0.028 0" />
      <geometry>
        <cylinder length="0.08" radius="0.055" />
      </geometry>
    </collision>
    <inertial>
      <origin rpy="1.5707963268 0 0" xyz="0 -0.028 0" />
      <mass value="0.575" />
      <inertia ixx="0.000741510416667" ixy="0" ixz="0" iyy="0.000741510416667" iyz="0" izz="0.0008696875" />
      <!-- Okay for now... forgot when cylinder is formed what direction is x pointing in -->
      <!--inertia ixx="0.00066963541" ixy="0" ixz="0" iyy="0.00066963541" iyz="0" izz="0.0008696875" /-->
    </inertial>
  </link>
  <gazebo reference="hip3">
    <material>Gazebo/Grey</material>
  </gazebo>
  <!-- Abduction joint. Joint names are: 8 9 10 11 -->
  <joint name="11" type="revolute">
    <parent link="body" />
    <child link="hip3" />
    <axis xyz="1 0 0" />
    <origin xyz="-0.2263 -0.07 0" />
    <limit effort="21" lower="-0.707" upper="0.707" velocity="37.7" />
    <dynamics damping="0.0" friction="0.0" />
  </joint>
  <!-- Transmission elements required for Gazebo -->
  <transmission name="transmission_11">
    <type>transmission_interface/SimpleTransmission</type>
    <joint name="11">
      <hardwareInterface>hardware_interface/EffortJointInterface</hardwareInterface>
    </joint>
    <actuator name="motor_11">
      <hardwareInterface>EffortJointInterface</hardwareInterface>
      <mechanicalReduction>1</mechanicalReduction>
    </actuator>
  </transmission>
  <!-- Upper leg -->
  <link name="upper3">
    <visual>
      <origin rpy="0 0 0" xyz="-0.103 0.022 0" />
      <geometry>
        <box size="0.206 0.022 0.055" />
      </geometry>
      <material name="silver" />
    </visual>
    <collision>
      <origin rpy="0 0 0" xyz="-0.103 0.022 0" />
      <geometry>
        <box size="0.206 0.022 0.055" />
      </geometry>
    </collision>
    <inertial>
      <origin rpy="0 0 0" xyz="-0.103 0.022 0" />
      <mass value="0.792" />
      <!--<inertia ixx="${upperLegIxx}" ixy="0" ixz="0" iyy="${upperLegIyy}" iyz="0" izz="${upperLegIzz}" /> -->
      <inertia ixx="0.000231594" ixy="0" ixz="0" iyy="0.003000426" iyz="0" izz="0.00283272" />
    </inertial>
  </link>
  <gazebo reference="upper3">
    <self_collide>0</self_collide>
    <material>Gazebo/DarkGrey</material>
  </gazebo>
  <!-- Hip joint. (Motor to upper leg). Joint names are: 0 2 4 6 -->
  <joint name="6" type="revolute">
    <parent link="hip3" />
    <child link="upper3" />
    <axis xyz="0 -1 0" />
    <origin xyz="0 -0.10098 0" />
    <!--  rpy="0 -0.3 0" -->
    <limit effort="21" lower="-1.57" upper="3.14" velocity="37.7" />
    <dynamics damping="0.0" friction="0.0" />
  </joint>
  <!-- Transmission elements required for Gazebo -->
  <transmission name="transmission_6">
    <type>transmission_interface/SimpleTransmission</type>
    <joint name="6">
      <hardwareInterface>hardware_interface/EffortJointInterface</hardwareInterface>
    </joint>
    <actuator name="motor_6">
      <hardwareInterface>EffortJointInterface</hardwareInterface>
      <mechanicalReduction>1</mechanicalReduction>
    </actuator>
  </transmission>
  <!-- Lower leg -->
  <link name="lower3">
    <self_collide>0</self_collide>
    <visual>
      <origin rpy="0 1.5707963268 0" xyz="0.103 0 0" />
      <geometry>
        <cylinder length="0.206" radius="0.013" />
      </geometry>
      <material name="darkgray" />
    </visual>
    <collision>
      <origin rpy="0 1.5707963268 0" xyz="0.103 0 0" />
      <geometry>
        <cylinder length="0.206" radius="0.013" />
      </geometry>
    </collision>
    <inertial>
      <origin rpy="0 0 0" xyz="0.103 0 0" />
      <mass value="0.075" />
      <!--inertia ixx="${lowerLegIxx}" ixy="0" ixz="0" iyy="${lowerLegIyy}" iyz="0" izz="${lowerLegIzz}" /-->
      <inertia ixx="2.193125e-05" ixy="0" ixz="0" iyy="0.00028413125" iyz="0" izz="0.00026825" />
    </inertial>
  </link>
  <gazebo reference="lower3">
    <material>Gazebo/Grey</material>
  </gazebo>
  <!-- Knee joint. Joint names are: 1 3 5 7 -->
  <joint name="7" type="revolute">
    <parent link="upper3" />
    <child link="lower3" />
    <axis xyz="0 1 0" />
    <origin xyz="-0.206 0 0" />
    <!--rpy="0 0.5 0"-->
    <!--<limit effort="${jointEffortLimit}" velocity="${jointSpeedLimit}" lower="0" upper="${pi}" />-->
    <limit effort="32" lower="-6.28" upper="6.28" velocity="25.1" />
    <dynamics damping="0.0" friction="0.0" />
  </joint>
  <!-- Transmission elements required for Gazebo -->
  <transmission name="transmission_7">
    <type>transmission_interface/SimpleTransmission</type>
    <joint name="7">
      <hardwareInterface>hardware_interface/EffortJointInterface</hardwareInterface>
    </joint>
    <actuator name="motor_7">
      <hardwareInterface>EffortJointInterface</hardwareInterface>
      <mechanicalReduction>1</mechanicalReduction>
    </actuator>
  </transmission>
  <!-- Toe -->
  <link name="toe3">
    <contact>
      <friction_anchor />
      <stiffness value="30000.0" />
      <damping value="1000.0" />
      <spinning_friction value="0.3" />
      <lateral_friction value="50.0" />
    </contact>
    <visual>
      <origin rpy="0 0 0" xyz="0 0 0" />
      <geometry>
        <sphere radius="0.02" />
      </geometry>
      <material name="darkgray" />
    </visual>
    <collision>
      <origin rpy="0 0 0" xyz="0 0 0" />
      <geometry>
        <sphere radius="0.02" />
      </geometry>
    </collision>
    <inertial>
      <mass value="0.015" />
      <inertia ixx="0.000025" ixy="0" ixz="0" iyy="0.000025" iyz="0" izz="0.000025" />
      <!-- <inertia ixx="2/5*${toeMass}*${toeRadius}*${toeRadius}"  ixy="0"  ixz="0" iyy="2/5*${toeMass}*${toeRadius}*${toeRadius}" iyz="0" izz="2/5*${toeMass}*${toeRadius}*${toeRadius}" /> -->
    </inertial>
  </link>
  <gazebo reference="toe3">
    <self_collide>0</self_collide>
    <material>Gazebo/Black</material>
    <collision>
      <surface>
        <bounce>
          <restitution_coefficient>0</restitution_coefficient>
          <threshold>1e+06</threshold>
        </bounce>
        <friction>
          <torsional>
            <coefficient>0.3</coefficient>
          </torsional>
          <ode>
            <mu>100.0</mu>
            <mu2>50.0</mu2>
          </ode>
          <bullet>
            <rolling_friction>0.3</rolling_friction>
            <friction2>50.0</friction2>
          </bullet>
        </friction>
        <contact>
          <bullet>
            <kp>30000.0</kp>
            <kd>1000.0</kd>
          </bullet>
          <ode>
            <kp>30000.0</kp>
            <kd>1000.0</kd>
          </ode>
        </contact>
      </surface>
    </collision>
  </gazebo>
  <joint name="jtoe3" type="fixed">
    <parent link="lower3" />
    <child link="toe3" />
    <origin xyz="0.206 0 -0.0" />
    <dynamics damping="0.0" friction="0.0" />
  </joint>
  <!-- Toe Plugins -->
  <gazebo reference="toe0">
    <sensor name="toe0_contact" type="contact">
      <plugin filename="libgazebo_ros_bumper.so" name="toe0_plugin">
        <alwaysOn>true</alwaysOn>
        <updateRate>500</updateRate>
        <bumperTopicName>gazebo/toe0_contact_state</bumperTopicName>
        <frameName>world</frameName>
      </plugin>
      <contact>
        <collision>toe0_collision</collision>
      </contact>
      <update_rate>500</update_rate>
    </sensor>
  </gazebo>
  <gazebo reference="toe1">
    <sensor name="toe1_contact" type="contact">
      <plugin filename="libgazebo_ros_bumper.so" name="toe1_plugin">
        <alwaysOn>true</alwaysOn>
        <updateRate>500</updateRate>
        <bumperTopicName>gazebo/toe1_contact_state</bumperTopicName>
        <frameName>world</frameName>
      </plugin>
      <contact>
        <collision>toe1_collision</collision>
      </contact>
      <update_rate>500</update_rate>
    </sensor>
  </gazebo>
  <gazebo reference="toe2">
    <sensor name="toe2_contact" type="contact">
      <plugin filename="libgazebo_ros_bumper.so" name="toe2_plugin">
        <alwaysOn>true</alwaysOn>
        <updateRate>500</updateRate>
        <bumperTopicName>gazebo/toe2_contact_state</bumperTopicName>
        <frameName>world</frameName>
      </plugin>
      <contact>
        <collision>toe2_collision</collision>
      </contact>
      <update_rate>500</update_rate>
    </sensor>
  </gazebo>
  <gazebo reference="toe3">
    <sensor name="toe3_contact" type="contact">
      <plugin filename="libgazebo_ros_bumper.so" name="toe3_plugin">
        <alwaysOn>true</alwaysOn>
        <updateRate>500</updateRate>
        <bumperTopicName>gazebo/toe3_contact_state</bumperTopicName>
        <frameName>world</frameName>
      </plugin>
      <contact>
        <collision>toe3_collision</collision>
      </contact>
      <update_rate>500</update_rate>
    </sensor>
  </gazebo>
  <!-- Preserve fixed joints -->
  <gazebo reference="jtoe0">
    <preserveFixedJoint>true</preserveFixedJoint>
  </gazebo>
  <gazebo reference="jtoe1">
    <preserveFixedJoint>true</preserveFixedJoint>
  </gazebo>
  <gazebo reference="jtoe2">
    <preserveFixedJoint>true</preserveFixedJoint>
  </gazebo>
  <gazebo reference="jtoe3">
    <preserveFixedJoint>true</preserveFixedJoint>
  </gazebo>
  <!-- TAIL -->
  <!-- Remark: Need to incorporate reasonable mass & inertia calc wrt tailLength -->
  <!-- Tail Links -->
  <link name="tail_link_0">
    <visual>
      <origin rpy="0 0 0" xyz="0 0 0.0734666666667" />
      <geometry>
        <cylinder length="0.146933333333" radius="0.02" />
      </geometry>
      <material name="gray" />
    </visual>
    <inertial>
      <origin rpy="0 0 0" xyz="0 0 0.0734666666667" />
      <mass value="0.001" />
      <!--<inertia ixx="${tailLinkMass/12*(3*0.02*0.02 + tailLength*tailLength)}" ixy="0" ixz="0" iyy="${tailLinkMass/12*(3*0.02*0.02 + tailLength*tailLength)}" iyz="0.0" izz="${tailLinkMass*(0.02*0.02)/2}" /> -->
      <!-- Assume inertia of a sphere & scale base of 2/5MR^2 -->
      <inertia ixx="2.77777777778e-06" ixy="0" ixz="0" iyy="2.77777777778e-06" iyz="0" izz="2.77777777778e-06" />
    </inertial>
    <!-- No need to add collision boxes for this -->
  </link>
  <gazebo reference="tail_link_0">
    <material>Gazebo/Gray</material>
  </gazebo>
  <link name="tail_link_1">
    <visual>
      <origin rpy="0 0 0" xyz="0 0 0.0734666666667" />
      <geometry>
        <cylinder length="0.146933333333" radius="0.02" />
      </geometry>
      <material name="gray" />
    </visual>
    <inertial>
      <origin rpy="0 0 0" xyz="0 0 0.0734666666667" />
      <mass value="0.001" />
      <inertia ixx="2.77777777778e-06" ixy="0" ixz="0" iyy="2.77777777778e-06" iyz="0" izz="2.77777777778e-06" />
    </inertial>
  </link>
  <gazebo reference="tail_link_1">
    <material>Gazebo/Gray</material>
  </gazebo>
  <link name="tail_link_2">
    <visual>
      <origin rpy="0 0 0" xyz="0 0 0.0734666666667" />
      <geometry>
        <cylinder length="0.146933333333" radius="0.02" />
      </geometry>
      <material name="gray" />
    </visual>
    <inertial>
      <origin rpy="0 0 0" xyz="0 0 0.0734666666667" />
      <mass value="0.001" />
      <inertia ixx="2.77777777778e-06" ixy="0" ixz="0" iyy="2.77777777778e-06" iyz="0" izz="2.77777777778e-06" />
    </inertial>
  </link>
  <gazebo reference="tail_link_2">
    <material>Gazebo/Gray</material>
  </gazebo>
  <link name="tail_link_3">
    <visual>
      <origin rpy="0 0 0" xyz="0 0 0.0734666666667" />
      <geometry>
        <cylinder length="0.146933333333" radius="0.02" />
      </geometry>
      <material name="gray" />
    </visual>
    <inertial>
      <origin rpy="0 0 0" xyz="0 0 0.0734666666667" />
      <mass value="0.001" />
      <inertia ixx="2.77777777778e-06" ixy="0" ixz="0" iyy="2.77777777778e-06" iyz="0" izz="2.77777777778e-06" />
    </inertial>
  </link>
  <gazebo reference="tail_link_3">
    <material>Gazebo/Gray</material>
  </gazebo>
  <link name="tail_link_4">
    <visual>
      <origin rpy="0 0 0" xyz="0 0 0.0734666666667" />
      <geometry>
        <cylinder length="0.146933333333" radius="0.02" />
      </geometry>
      <material name="gray" />
    </visual>
    <inertial>
      <origin rpy="0 0 0" xyz="0 0 0.0734666666667" />
      <mass value="0.001" />
      <inertia ixx="2.77777777778e-06" ixy="0" ixz="0" iyy="2.77777777778e-06" iyz="0" izz="2.77777777778e-06" />
    </inertial>
  </link>
  <gazebo reference="tail_link_4">
    <material>Gazebo/Gray</material>
  </gazebo>
  <link name="tail_link_5">
    <visual>
      <origin rpy="0 0 0" xyz="0 0 0.0734666666667" />
      <geometry>
        <cylinder length="0.146933333333" radius="0.02" />
      </geometry>
      <material name="gray" />
    </visual>
    <inertial>
      <origin rpy="0 0 0" xyz="0 0 0.0734666666667" />
      <mass value="0.001" />
      <inertia ixx="2.77777777778e-06" ixy="0" ixz="0" iyy="2.77777777778e-06" iyz="0" izz="2.77777777778e-06" />
    </inertial>
  </link>
  <gazebo reference="tail_link_5">
    <material>Gazebo/Gray</material>
  </gazebo>
  <!--
	<link name="tail_link_6">
		<visual>
			<origin rpy="0 0 0" xyz="0 0 ${tailLength/2}" />
			<geometry>
				<cylinder radius="0.02" length="${tailLength}" />
			</geometry>
			<material name="gray" />
		</visual>
		<inertial>
			<origin xyz="0 0 ${tailLength/2}" rpy="0 0 0" />
			<mass value="${tailLinkMass}" />
			<inertia ixx="${1e-04/(tailNum*tailNum)}" ixy="0" ixz="0" iyy="${1e-04/(tailNum*tailNum)}" iyz="0" izz="${1e-04/(tailNum*tailNum)}" />
		</inertial>
	</link>

	<gazebo reference="tail_link_6">
		<material>Gazebo/Gray</material>
	</gazebo>
	
	<link name="tail_link_7">
		<visual>
			<origin rpy="0 0 0" xyz="0 0 ${tailLength/2}" />
			<geometry>
				<cylinder radius="0.02" length="${tailLength}" />
			</geometry>
			<material name="gray" />
		</visual>
		<inertial>
			<origin xyz="0 0 ${tailLength/2}" rpy="0 0 0" />
			<mass value="${tailLinkMass}" />
			<inertia ixx="${1e-04/(tailNum*tailNum)}" ixy="0" ixz="0" iyy="${1e-04/(tailNum*tailNum)}" iyz="0" izz="${1e-04/(tailNum*tailNum)}" />
		</inertial>
	</link>

	<gazebo reference="tail_link_7">
		<material>Gazebo/Gray</material>
	</gazebo>

	<link name="tail_link_8">
		<visual>
			<origin rpy="0 0 0" xyz="0 0 ${tailLength/2}" />
			<geometry>
				<cylinder radius="0.02" length="${tailLength}" />
			</geometry>
			<material name="gray" />
		</visual>
		<inertial>
			<origin xyz="0 0 ${tailLength/2}" rpy="0 0 0" />
			<mass value="${tailLinkMass}" />
			<inertia ixx="${1e-04/(tailNum*tailNum)}" ixy="0" ixz="0" iyy="${1e-04/(tailNum*tailNum)}" iyz="0" izz="${1e-04/(tailNum*tailNum)}" />
		</inertial>
	</link>

	<gazebo reference="tail_link_8">
		<material>Gazebo/Gray</material>
	</gazebo>

	<link name="tail_link_9">
		<visual>
			<origin rpy="0 0 0" xyz="0 0 ${tailLength/2}" />
			<geometry>
				<cylinder radius="0.02" length="${tailLength}" />
			</geometry>
			<material name="gray" />
		</visual>
		<inertial>
			<origin xyz="0 0 ${tailLength/2}" rpy="0 0 0" />
			<mass value="${tailLinkMass}" />
			<inertia ixx="${1e-04/(tailNum*tailNum)}" ixy="0" ixz="0" iyy="${1e-04/(tailNum*tailNum)}" iyz="0" izz="${1e-04/(tailNum*tailNum)}" />
		</inertial>
	</link> 

	<gazebo reference="tail_link_9">
		<material>Gazebo/Gray</material>
	</gazebo> -->
  <link name="tail_mass">
    <visual>
      <origin rpy="0 0 0" xyz="0 0 0" />
      <geometry>
        <sphere radius="0.04" />
      </geometry>
      <material name="gray" />
    </visual>
    <inertial>
      <mass value="0.2764" />
      <inertia ixx="2.764e-04" ixy="0" ixz="0" iyy="2.764e-04" iyz="0" izz="2.764e-04" />
    </inertial>
    <collision>
      <origin rpy="0 0 0" xyz=" 0 0 0" />
      <geometry>
        <sphere radius="0.04" />
      </geometry>
    </collision>
  </link>
  <gazebo reference="tail_mass">
    <material>Gazebo/Gray</material>
    <self_collide>1</self_collide>
  </gazebo>
  <!-- Tail Joints -->
  <!-- Non-planar Tail -->
  <!--<joint name="body_tail_joint_0" type="revolute">
		<parent link="body" />
		<child link="tail_link_0" />
		<axis xyz="1 0 0" />
		<origin xyz="0 0 0" rpy="0 0 0" />
		<limit effort="50" lower="-1.57" upper="1.57" velocity="40" />
		<dynamics damping="0.0" friction="0.0" />
	</joint>-->
  <!-- Planar Tail -->
  <joint name="body_tail_joint_0" type="revolute">
    <parent link="body" />
    <child link="tail_link_0" />
    <axis xyz="0 1 0" />
    <origin rpy="0 0 0" xyz="0 0 0" />
    <limit effort="50" lower="-1.57" upper="1.57" velocity="40" />
    <dynamics damping="0.0" friction="0.0" />
  </joint>
  <joint name="body_tail_joint_1" type="revolute">
    <parent link="tail_link_0" />
    <child link="tail_link_1" />
    <axis xyz="0 1 0" />
    <origin rpy="0 0 0" xyz="0 0 0.146933333333" />
    <limit effort="50" lower="-1.57" upper="1.57" velocity="40" />
    <dynamics damping="0.0" friction="0.0" />
  </joint>
  <joint name="body_tail_joint_2" type="revolute">
    <parent link="tail_link_1" />
    <child link="tail_link_2" />
    <axis xyz="0 1 0" />
    <origin rpy="0 0 0" xyz="0 0 0.146933333333" />
    <limit effort="50" lower="-1.57" upper="1.57" velocity="40" />
    <dynamics damping="0.0" friction="0.0" />
  </joint>
  <joint name="body_tail_joint_3" type="revolute">
    <parent link="tail_link_2" />
    <child link="tail_link_3" />
    <axis xyz="0 1 0" />
    <origin rpy="0 0 0" xyz="0 0 0.146933333333" />
    <limit effort="50" lower="-1.57" upper="1.57" velocity="40" />
    <dynamics damping="0.0" friction="0.0" />
  </joint>
  <joint name="body_tail_joint_4" type="revolute">
    <parent link="tail_link_3" />
    <child link="tail_link_4" />
    <axis xyz="0 1 0" />
    <origin rpy="0 0 0" xyz="0 0 0.146933333333" />
    <limit effort="50" lower="-1.57" upper="1.57" velocity="40" />
    <dynamics damping="0.0" friction="0.0" />
  </joint>
  <joint name="body_tail_joint_5" type="revolute">
    <parent link="tail_link_4" />
    <child link="tail_link_5" />
    <axis xyz="0 1 0" />
    <origin rpy="0 0 0" xyz="0 0 0.146933333333" />
    <limit effort="50" lower="-1.57" upper="1.57" velocity="40" />
    <dynamics damping="0.0" friction="0.0" />
  </joint>
  <!--
	<joint name="body_tail_joint_6" type="revolute">
		<parent link="tail_link_5" />
		<child link="tail_link_6" />
		<axis xyz="0 1 0" />
		<origin xyz="0 0 ${tailLength}" rpy="0 0 0" />
		<limit effort="50" lower="-1.57" upper="1.57" velocity="40" />
		<dynamics damping="0.0" friction="0.0" />
	</joint>

	<joint name="body_tail_joint_7" type="revolute">
		<parent link="tail_link_6" />
		<child link="tail_link_7" />
		<axis xyz="0 1 0" />
		<origin xyz="0 0 ${tailLength}" rpy="0 0 0" />
		<limit effort="50" lower="-1.57" upper="1.57" velocity="40" />
		<dynamics damping="0.0" friction="0.0" />
	</joint>

	<joint name="body_tail_joint_8" type="revolute">
		<parent link="tail_link_7" />
		<child link="tail_link_8" />
		<axis xyz="0 1 0" />
		<origin xyz="0 0 ${tailLength}" rpy="0 0 0" />
		<limit effort="50" lower="-1.57" upper="1.57" velocity="40" />
		<dynamics damping="0.0" friction="0.0" />
	</joint>

	<joint name="body_tail_joint_9" type="revolute">
		<parent link="tail_link_8" />
		<child link="tail_link_9" />
		<axis xyz="0 1 0" />
		<origin xyz="0 0 ${tailLength}" rpy="0 0 0" />
		<limit effort="50" lower="-1.57" upper="1.57" velocity="40" />
		<dynamics damping="0.0" friction="0.0" />
	</joint> -->
  <joint name="tail_link_mass_joint" type="fixed">
    <parent link="tail_link_5" />
    <child link="tail_mass" />
    <origin xyz="0 0 0.146933333333" />
    <dynamic damping="0.0" friction="0.0" />
  </joint>
  <!-- Transmission Elements Required for Gazebo Control -->
  <transmission name="transmission_body_tail_joint_0">
    <type>transmission_interface/SimpleTransmission</type>
    <joint name="body_tail_joint_0">
      <hardwareInterface>hardware_interface/EffortJointInterface</hardwareInterface>
    </joint>
    <actuator name="motor_body_tail_joint_0">
      <hardwareInterface>hardware_interface/EffortJointInterface</hardwareInterface>
      <mechanicalReduction>1</mechanicalReduction>
    </actuator>
  </transmission>
  <transmission name="transmission_body_tail_joint_1">
    <type>transmission_interface/SimpleTransmission</type>
    <joint name="body_tail_joint_1">
      <hardwareInterface>hardware_interface/EffortJointInterface</hardwareInterface>
    </joint>
    <actuator name="motor_body_tail_joint_1">
      <hardwareInterface>hardware_interface/EffortJointInterface</hardwareInterface>
      <mechanicalReduction>1</mechanicalReduction>
    </actuator>
  </transmission>
  <transmission name="transmission_body_tail_joint_2">
    <type>transmission_interface/SimpleTransmission</type>
    <joint name="body_tail_joint_2">
      <hardwareInterface>hardware_interface/EffortJointInterface</hardwareInterface>
    </joint>
    <actuator name="motor_body_tail_joint_2">
      <hardwareInterface>hardware_interface/EffortJointInterface</hardwareInterface>
      <mechanicalReduction>1</mechanicalReduction>
    </actuator>
  </transmission>
  <transmission name="transmission_body_tail_joint_3">
    <type>transmission_interface/SimpleTransmission</type>
    <joint name="body_tail_joint_3">
      <hardwareInterface>hardware_interface/EffortJointInterface</hardwareInterface>
    </joint>
    <actuator name="motor_body_tail_joint_3">
      <hardwareInterface>hardware_interface/EffortJointInterface</hardwareInterface>
      <mechanicalReduction>1</mechanicalReduction>
    </actuator>
  </transmission>
  <transmission name="transmission_body_tail_joint_4">
    <type>transmission_interface/SimpleTransmission</type>
    <joint name="body_tail_joint_4">
      <hardwareInterface>hardware_interface/EffortJointInterface</hardwareInterface>
    </joint>
    <actuator name="motor_body_tail_joint_4">
      <hardwareInterface>hardware_interface/EffortJointInterface</hardwareInterface>
      <mechanicalReduction>1</mechanicalReduction>
    </actuator>
  </transmission>
  <transmission name="transmission_body_tail_joint_5">
    <type>transmission_interface/SimpleTransmission</type>
    <joint name="body_tail_joint_5">
      <hardwareInterface>hardware_interface/EffortJointInterface</hardwareInterface>
    </joint>
    <actuator name="motor_body_tail_joint_5">
      <hardwareInterface>hardware_interface/EffortJointInterface</hardwareInterface>
      <mechanicalReduction>1</mechanicalReduction>
    </actuator>
  </transmission>
  <!--
	<transmission name="transmission_body_tail_joint_6">
		<type>transmission_interface/SimpleTransmission</type>
		<joint name="body_tail_joint_6">
			<hardwareInterface>hardware_interface/EffortJointInterface</hardwareInterface>
		</joint>
		<actuator name="motor_body_tail_joint_6">
			<hardwareInterface>hardware_interface/EffortJointInterface</hardwareInterface>
			<mechanicalReduction>1</mechanicalReduction>
		</actuator>
	</transmission>

	<transmission name="transmission_body_tail_joint_7">
		<type>transmission_interface/SimpleTransmission</type>
		<joint name="body_tail_joint_7">
			<hardwareInterface>hardware_interface/EffortJointInterface</hardwareInterface>
		</joint>
		<actuator name="motor_body_tail_joint_7">
			<hardwareInterface>hardware_interface/EffortJointInterface</hardwareInterface>
			<mechanicalReduction>1</mechanicalReduction>
		</actuator>
	</transmission>

	<transmission name="transmission_body_tail_joint_8">
		<type>transmission_interface/SimpleTransmission</type>
		<joint name="body_tail_joint_8">
			<hardwareInterface>hardware_interface/EffortJointInterface</hardwareInterface>
		</joint>
		<actuator name="motor_body_tail_joint_8">
			<hardwareInterface>hardware_interface/EffortJointInterface</hardwareInterface>
			<mechanicalReduction>1</mechanicalReduction>
		</actuator>
	</transmission>

	<transmission name="transmission_body_tail_joint_9">
		<type>transmission_interface/SimpleTransmission</type>
		<joint name="body_tail_joint_9">
			<hardwareInterface>hardware_interface/EffortJointInterface</hardwareInterface>
		</joint>
		<actuator name="motor_body_tail_joint_9">
			<hardwareInterface>hardware_interface/EffortJointInterface</hardwareInterface>
			<mechanicalReduction>1</mechanicalReduction>
		</actuator>
	</transmission> -->
</robot>