<sdf version='1.6'>
  <model name='pupperv2_description'>
    <link name='base_link'>
      <pose frame=''>0 0 0 0 -0 0</pose>
      <inertial>
        <pose frame=''>0.032176 -0 0.014228 0 -0 0</pose>
        <mass>0.84791</mass>
        <inertia>
          <ixx>0.00372642</ixx>
          <ixy>1.18475e-06</ixy>
          <ixz>0.00193168</ixz>
          <iyy>0.0064904</iyy>
          <iyz>1.71595e-07</iyz>
          <izz>0.00460514</izz>
        </inertia>
      </inertial>
      <collision name='base_link_collision'>
        <pose frame=''>0 0 0 0 -0 0</pose>
        <geometry>
          <mesh>
            <scale>1 1 1</scale>
            <uri>model://pupperv2_description/obj_meshes/Cube003.obj</uri>
          </mesh>
        </geometry>
      </collision>
      <collision name='base_link_fixed_joint_lump__camera_link_collision_1'>
        <pose frame=''>0.13641 0 -0.05661 0 -0 0</pose>
        <geometry>
          <mesh>
            <scale>1 1 1</scale>
            <uri>model://hector_sensors_description/meshes/asus_camera/asus_camera_simple.dae</uri>
          </mesh>
        </geometry>
      </collision>
      <collision name='base_link_fixed_joint_lump__hokuyo_frame_collision_2'>
        <pose frame=''>0 0 0.07511 0 -0 0</pose>
        <geometry>
          <box>
            <size>0.058 0.058 0.087</size>
          </box>
        </geometry>
        <surface>
          <contact>
            <ode/>
          </contact>
          <friction>
            <ode/>
          </friction>
        </surface>
      </collision>
      <visual name='base_link_visual'>
        <pose frame=''>0 0 0 0 -0 0</pose>
        <geometry>
          <mesh>
            <scale>1 1 1</scale>
            <uri>model://pupperv2_description/obj_meshes/Cube003.obj</uri>
          </mesh>
        </geometry>
      </visual>
      <visual name='base_link_fixed_joint_lump__camera_link_visual_1'>
        <pose frame=''>0.13641 0 -0.05661 0 -0 0</pose>
        <geometry>
          <mesh>
            <scale>1 1 1</scale>
            <uri>model://hector_sensors_description/meshes/asus_camera/asus_camera_simple.dae</uri>
          </mesh>
        </geometry>
      </visual>
      <visual name='base_link_fixed_joint_lump__hokuyo_frame_visual_2'>
        <pose frame=''>0 0 0.08661 0 -0 0</pose>
        <geometry>
          <mesh>
            <scale>1 1 1</scale>
            <uri>model://hector_sensors_description/meshes/hokuyo_utm30lx/hokuyo_utm_30lx.dae</uri>
          </mesh>
        </geometry>
        <material>
          <script>
            <uri>__default__</uri>
            <name>__default__</name>
          </script>
        </material>
      </visual>
      <velocity_decay/>
      <sensor name='camera' type='depth'>
        <update_rate>20</update_rate>
        <camera name='__default__'>
          <horizontal_fov>1.09607</horizontal_fov>
          <image>
            <format>R8G8B8</format>
            <width>640</width>
            <height>480</height>
          </image>
          <clip>
            <near>0.5</near>
            <far>9</far>
          </clip>
        </camera>
        <plugin name='camera_camera_controller' filename='libgazebo_ros_openni_kinect.so'>
          <imageTopicName>camera/rgb/image_raw</imageTopicName>
          <cameraInfoTopicName>camera/rgb/camera_info</cameraInfoTopicName>
          <depthImageTopicName>camera/depth/image_raw</depthImageTopicName>
          <depthImageCameraInfoTopicName>camera/depth/camera_info</depthImageCameraInfoTopicName>
          <pointCloudTopicName>camera/depth/points</pointCloudTopicName>
          <frameName>camera_depth_optical_frame</frameName>
        </plugin>
        <pose frame=''>0.13641 0.049 -0.05661 0 -0 0</pose>
      </sensor>
      <gravity>1</gravity>
      <velocity_decay/>
      <sensor name='hokuyo' type='ray'>
        <always_on>1</always_on>
        <update_rate>30</update_rate>
        <visualize>0</visualize>
        <ray>
          <scan>
            <horizontal>
              <samples>1040</samples>
              <resolution>1</resolution>
              <min_angle>2.26893</min_angle>
              <max_angle>-2.26893</max_angle>
            </horizontal>
          </scan>
          <range>
            <min>0.2</min>
            <max>30</max>
            <resolution>0.01</resolution>
          </range>
          <noise>
            <type>gaussian</type>
            <mean>0</mean>
            <stddev>0.004</stddev>
          </noise>
        </ray>
        <plugin name='gazebo_ros_hokuyo_controller' filename='libgazebo_ros_laser.so'>
          <topicName>scan</topicName>
          <frameName>hokuyo_frame</frameName>
        </plugin>
        <pose frame=''>0 0 0.08661 0 -0 0</pose>
      </sensor>
    </link>
    <link name='FL_hip'>
      <pose frame=''>0.036007 0.0466 0.00461 0 -0 0</pose>
      <inertial>
        <pose frame=''>0.01877 0.003295 0.00039 0 -0 0</pose>
        <mass>0.032035</mass>
        <inertia>
          <ixx>5.9933e-06</ixx>
          <ixy>4.4808e-07</ixy>
          <ixz>2.4371e-10</ixz>
          <iyy>2.9538e-06</iyy>
          <iyz>6.1996e-08</iyz>
          <izz>5.7278e-06</izz>
        </inertia>
      </inertial>
      <collision name='FL_hip_collision'>
        <pose frame=''>0 0 0 0 -0 0</pose>
        <geometry>
          <box>
            <size>0.03569 0.0483 0.025</size>
          </box>
        </geometry>
      </collision>
      <visual name='FL_hip_visual'>
        <pose frame=''>0.00795 0.00329 0.00039 1.5708 -0 0</pose>
        <geometry>
          <cylinder>
            <length>0.0483</length>
            <radius>0.0152</radius>
          </cylinder>
        </geometry>
      </visual>
    </link>
    <joint name='base_link_FL_hip' type='revolute'>
      <child>FL_hip</child>
      <parent>base_link</parent>
      <axis>
        <xyz>1 0 0</xyz>
        <limit>
          <lower>-0.7854</lower>
          <upper>0.7854</upper>
          <effort>100</effort>
          <velocity>2.5</velocity>
        </limit>
        <dynamics>
          <spring_reference>0</spring_reference>
          <spring_stiffness>0</spring_stiffness>
        </dynamics>
        <use_parent_model_frame>1</use_parent_model_frame>
      </axis>
    </joint>
    <link name='FL_upper_leg'>
      <pose frame=''>0.051257 0.07195 0.00461 0 -0 0</pose>
      <inertial>
        <pose frame=''>0.000116 0.025203 -0.048064 0 -0 0</pose>
        <mass>0.054665</mass>
        <inertia>
          <ixx>2.4386e-05</ixx>
          <ixy>1.682e-10</ixy>
          <ixz>2.6061e-07</ixz>
          <iyy>2.3437e-05</iyy>
          <iyz>2.7137e-07</iyz>
          <izz>6.6679e-06</izz>
        </inertia>
      </inertial>
      <collision name='FL_upper_leg_collision'>
        <pose frame=''>0 0 0 0 -0 0</pose>
        <geometry>
          <mesh>
            <scale>1 1 1</scale>
            <uri>model://pupperv2_description/meshes/FL_upper_leg.STL</uri>
          </mesh>
        </geometry>
      </collision>
      <visual name='FL_upper_leg_visual'>
        <pose frame=''>0 0 0 0 -0 0</pose>
        <geometry>
          <mesh>
            <scale>1 1 1</scale>
            <uri>model://pupperv2_description/meshes/FL_upper_leg.STL</uri>
          </mesh>
        </geometry>
      </visual>
    </link>
    <joint name='FL_hip_FL_upper_leg' type='revolute'>
      <child>FL_upper_leg</child>
      <parent>FL_hip</parent>
      <axis>
        <xyz>0 1 0</xyz>
        <limit>
          <lower>-1.309</lower>
          <upper>4.4506</upper>
          <effort>100</effort>
          <velocity>2.5</velocity>
        </limit>
        <dynamics>
          <spring_reference>0</spring_reference>
          <spring_stiffness>0</spring_stiffness>
        </dynamics>
        <use_parent_model_frame>1</use_parent_model_frame>
      </axis>
    </joint>
    <link name='FL_lower_leg'>
      <pose frame=''>0.051257 0.07195 -0.07539 0 -0 0</pose>
      <inertial>
        <pose frame=''>2.9e-05 0.004388 -0.047513 0 -0 0</pose>
        <mass>0.0185279</mass>
        <inertia>
          <ixx>2.69352e-05</ixx>
          <ixy>-1.47429e-09</ixy>
          <ixz>-5.82501e-08</ixz>
          <iyy>2.71324e-05</iyy>
          <iyz>1.19137e-06</iyz>
          <izz>6.50898e-07</izz>
        </inertia>
      </inertial>
      <collision name='FL_lower_leg_collision'>
        <pose frame=''>0 0 0 0 -0 0</pose>
        <geometry>
          <mesh>
            <scale>1 1 1</scale>
            <uri>model://pupperv2_description/meshes/FL_lower_leg.STL</uri>
          </mesh>
        </geometry>
      </collision>
      <collision name='FL_lower_leg_fixed_joint_lump__FL_toe_collision_1'>
        <pose frame=''>0 0.008325 -0.11 0 -0 0</pose>
        <geometry>
          <mesh>
            <scale>1 1 1</scale>
            <uri>model://pupperv2_description/meshes/FL_toe.STL</uri>
          </mesh>
        </geometry>
        <surface>
          <contact>
            <ode>
              <kp>1e+06</kp>
              <kd>1</kd>
              <max_vel>0</max_vel>
              <min_depth>0.001</min_depth>
            </ode>
          </contact>
          <friction>
            <ode>
              <mu>0.8</mu>
              <mu2>0.8</mu2>
            </ode>
          </friction>
        </surface>
      </collision>
      <visual name='FL_lower_leg_visual'>
        <pose frame=''>0 0 0 0 -0 0</pose>
        <geometry>
          <mesh>
            <scale>1 1 1</scale>
            <uri>model://pupperv2_description/meshes/FL_lower_leg.STL</uri>
          </mesh>
        </geometry>
      </visual>
      <visual name='FL_lower_leg_fixed_joint_lump__FL_toe_visual_1'>
        <pose frame=''>0 0.008325 -0.11 0 -0 0</pose>
        <geometry>
          <mesh>
            <scale>1 1 1</scale>
            <uri>model://pupperv2_description/meshes/FL_toe.STL</uri>
          </mesh>
        </geometry>
        <material>
          <script>
            <uri>__default__</uri>
            <name>__default__</name>
          </script>
        </material>
      </visual>
      <gravity>1</gravity>
      <velocity_decay/>
    </link>
    <joint name='FL_upper_leg_FL_lower_leg' type='revolute'>
      <child>FL_lower_leg</child>
      <parent>FL_upper_leg</parent>
      <axis>
        <xyz>0 1 0</xyz>
        <limit>
          <lower>-2.8798</lower>
          <upper>2.8798</upper>
          <effort>100</effort>
          <velocity>2.5</velocity>
        </limit>
        <dynamics>
          <spring_reference>0</spring_reference>
          <spring_stiffness>0</spring_stiffness>
        </dynamics>
        <use_parent_model_frame>1</use_parent_model_frame>
      </axis>
    </joint>
    <link name='FR_hip'>
      <pose frame=''>0.035885 -0.0474 0.00461 0 -0 0</pose>
      <inertial>
        <pose frame=''>0.018798 -0.003274 0.000397 0 -0 0</pose>
        <mass>0.032069</mass>
        <inertia>
          <ixx>5.9912e-06</ixx>
          <ixy>-4.4714e-07</ixy>
          <ixz>1.8534e-10</ixz>
          <iyy>2.954e-06</iyy>
          <iyz>-6.2909e-08</iyz>
          <izz>5.7295e-06</izz>
        </inertia>
      </inertial>
      <collision name='FR_hip_collision'>
        <pose frame=''>0 0 0 0 -0 0</pose>
        <geometry>
          <mesh>
            <scale>1 1 1</scale>
            <uri>model://pupperv2_description/meshes/FR_hip.STL</uri>
          </mesh>
        </geometry>
      </collision>
      <visual name='FR_hip_visual'>
        <pose frame=''>0 0 0 0 -0 0</pose>
        <geometry>
          <mesh>
            <scale>1 1 1</scale>
            <uri>model://pupperv2_description/meshes/FR_hip.STL</uri>
          </mesh>
        </geometry>
      </visual>
    </link>
    <joint name='base_link_FR_hip' type='revolute'>
      <child>FR_hip</child>
      <parent>base_link</parent>
      <axis>
        <xyz>1 0 0</xyz>
        <limit>
          <lower>-0.7854</lower>
          <upper>0.7854</upper>
          <effort>100</effort>
          <velocity>2.5</velocity>
        </limit>
        <dynamics>
          <spring_reference>0</spring_reference>
          <spring_stiffness>0</spring_stiffness>
        </dynamics>
        <use_parent_model_frame>1</use_parent_model_frame>
      </axis>
    </joint>
    <link name='FR_upper_leg'>
      <pose frame=''>0.051137 -0.07275 0.00461 0 -0 0</pose>
      <inertial>
        <pose frame=''>-0.000116 -0.025203 -0.048064 0 -0 0</pose>
        <mass>0.054665</mass>
        <inertia>
          <ixx>2.4386e-05</ixx>
          <ixy>1.682e-10</ixy>
          <ixz>-2.6061e-07</ixz>
          <iyy>2.3437e-05</iyy>
          <iyz>-2.7137e-07</iyz>
          <izz>6.6679e-06</izz>
        </inertia>
      </inertial>
      <collision name='FR_upper_leg_collision'>
        <pose frame=''>0 0 0 0 -0 0</pose>
        <geometry>
          <mesh>
            <scale>1 1 1</scale>
            <uri>model://pupperv2_description/meshes/FR_upper_leg.STL</uri>
          </mesh>
        </geometry>
      </collision>
      <visual name='FR_upper_leg_visual'>
        <pose frame=''>0 0 0 0 -0 0</pose>
        <geometry>
          <mesh>
            <scale>1 1 1</scale>
            <uri>model://pupperv2_description/meshes/FR_upper_leg.STL</uri>
          </mesh>
        </geometry>
      </visual>
    </link>
    <joint name='FR_hip_FR_upper_leg' type='revolute'>
      <child>FR_upper_leg</child>
      <parent>FR_hip</parent>
      <axis>
        <xyz>0 1 0</xyz>
        <limit>
          <lower>-4.4506</lower>
          <upper>1.309</upper>
          <effort>100</effort>
          <velocity>2.5</velocity>
        </limit>
        <dynamics>
          <spring_reference>0</spring_reference>
          <spring_stiffness>0</spring_stiffness>
        </dynamics>
        <use_parent_model_frame>1</use_parent_model_frame>
      </axis>
    </joint>
    <link name='FR_lower_leg'>
      <pose frame=''>0.051137 -0.07275 -0.07539 0 -0 0</pose>
      <inertial>
        <pose frame=''>3.2e-05 -0.004401 -0.047451 0 -0 0</pose>
        <mass>0.0185509</mass>
        <inertia>
          <ixx>2.6944e-05</ixx>
          <ixy>1.53789e-09</ixy>
          <ixz>-5.9142e-08</ixz>
          <iyy>2.71415e-05</iyy>
          <iyz>-1.19065e-06</iyz>
          <izz>6.51218e-07</izz>
        </inertia>
      </inertial>
      <collision name='FR_lower_leg_collision'>
        <pose frame=''>0 0 0 0 -0 0</pose>
        <geometry>
          <mesh>
            <scale>1 1 1</scale>
            <uri>model://pupperv2_description/meshes/FR_lower_leg.STL</uri>
          </mesh>
        </geometry>
      </collision>
      <collision name='FR_lower_leg_fixed_joint_lump__FR_toe_collision_1'>
        <pose frame=''>0 -0.008325 -0.11 0 -0 0</pose>
        <geometry>
          <mesh>
            <scale>1 1 1</scale>
            <uri>model://pupperv2_description/meshes/FR_toe.STL</uri>
          </mesh>
        </geometry>
        <surface>
          <contact>
            <ode>
              <kp>1e+06</kp>
              <kd>1</kd>
              <max_vel>0</max_vel>
              <min_depth>0.001</min_depth>
            </ode>
          </contact>
          <friction>
            <ode>
              <mu>0.8</mu>
              <mu2>0.8</mu2>
            </ode>
          </friction>
        </surface>
      </collision>
      <visual name='FR_lower_leg_visual'>
        <pose frame=''>0 0 0 0 -0 0</pose>
        <geometry>
          <mesh>
            <scale>1 1 1</scale>
            <uri>model://pupperv2_description/meshes/FR_lower_leg.STL</uri>
          </mesh>
        </geometry>
      </visual>
      <visual name='FR_lower_leg_fixed_joint_lump__FR_toe_visual_1'>
        <pose frame=''>0 -0.008325 -0.11 0 -0 0</pose>
        <geometry>
          <mesh>
            <scale>1 1 1</scale>
            <uri>model://pupperv2_description/meshes/FR_toe.STL</uri>
          </mesh>
        </geometry>
        <material>
          <script>
            <uri>__default__</uri>
            <name>__default__</name>
          </script>
        </material>
      </visual>
      <gravity>1</gravity>
      <velocity_decay/>
    </link>
    <joint name='FR_upper_leg_FR_lower_leg' type='revolute'>
      <child>FR_lower_leg</child>
      <parent>FR_upper_leg</parent>
      <axis>
        <xyz>0 1 0</xyz>
        <limit>
          <lower>-2.8798</lower>
          <upper>2.8798</upper>
          <effort>100</effort>
          <velocity>2.5</velocity>
        </limit>
        <dynamics>
          <spring_reference>0</spring_reference>
          <spring_stiffness>0</spring_stiffness>
        </dynamics>
        <use_parent_model_frame>1</use_parent_model_frame>
      </axis>
    </joint>
    <link name='RL_hip'>
      <pose frame=''>-0.12272 0.0466 0.00461 0 -0 0</pose>
      <inertial>
        <pose frame=''>-0.022505 0.003295 0.00039 0 -0 0</pose>
        <mass>0.032035</mass>
        <inertia>
          <ixx>5.9933e-06</ixx>
          <ixy>4.4808e-07</ixy>
          <ixz>2.4371e-10</ixz>
          <iyy>2.9538e-06</iyy>
          <iyz>6.1996e-08</iyz>
          <izz>5.7278e-06</izz>
        </inertia>
      </inertial>
      <collision name='RL_hip_collision'>
        <pose frame=''>0 0 0 0 -0 0</pose>
        <geometry>
          <mesh>
            <scale>1 1 1</scale>
            <uri>model://pupperv2_description/meshes/RL_hip.STL</uri>
          </mesh>
        </geometry>
      </collision>
      <visual name='RL_hip_visual'>
        <pose frame=''>0 0 0 0 -0 0</pose>
        <geometry>
          <mesh>
            <scale>1 1 1</scale>
            <uri>model://pupperv2_description/meshes/RL_hip.STL</uri>
          </mesh>
        </geometry>
      </visual>
    </link>
    <joint name='base_link_RL_hip' type='revolute'>
      <child>RL_hip</child>
      <parent>base_link</parent>
      <axis>
        <xyz>1 0 0</xyz>
        <limit>
          <lower>-0.7854</lower>
          <upper>0.7854</upper>
          <effort>100</effort>
          <velocity>2.5</velocity>
        </limit>
        <dynamics>
          <spring_reference>0</spring_reference>
          <spring_stiffness>0</spring_stiffness>
        </dynamics>
        <use_parent_model_frame>1</use_parent_model_frame>
      </axis>
    </joint>
    <link name='RL_upper_leg'>
      <pose frame=''>-0.148745 0.07195 0.00461 0 0.001131 0</pose>
      <inertial>
        <pose frame=''>0.000116 0.025203 -0.048064 0 -0 0</pose>
        <mass>0.054665</mass>
        <inertia>
          <ixx>2.4386e-05</ixx>
          <ixy>1.682e-10</ixy>
          <ixz>2.6061e-07</ixz>
          <iyy>2.3437e-05</iyy>
          <iyz>2.7137e-07</iyz>
          <izz>6.6679e-06</izz>
        </inertia>
      </inertial>
      <collision name='RL_upper_leg_collision'>
        <pose frame=''>0 0 0 0 -0 0</pose>
        <geometry>
          <mesh>
            <scale>1 1 1</scale>
            <uri>model://pupperv2_description/meshes/RL_upper_leg.STL</uri>
          </mesh>
        </geometry>
      </collision>
      <visual name='RL_upper_leg_visual'>
        <pose frame=''>0 0 0 0 -0 0</pose>
        <geometry>
          <mesh>
            <scale>1 1 1</scale>
            <uri>model://pupperv2_description/meshes/RL_upper_leg.STL</uri>
          </mesh>
        </geometry>
      </visual>
    </link>
    <joint name='RL_hip_RL_upper_leg' type='revolute'>
      <child>RL_upper_leg</child>
      <parent>RL_hip</parent>
      <axis>
        <xyz>0 1 0</xyz>
        <limit>
          <lower>-1.309</lower>
          <upper>4.4506</upper>
          <effort>100</effort>
          <velocity>2.5</velocity>
        </limit>
        <dynamics>
          <spring_reference>0</spring_reference>
          <spring_stiffness>0</spring_stiffness>
        </dynamics>
        <use_parent_model_frame>1</use_parent_model_frame>
      </axis>
    </joint>
    <link name='RL_lower_leg'>
      <pose frame=''>-0.148835 0.07195 -0.07539 0 -0 0</pose>
      <inertial>
        <pose frame=''>2.9e-05 0.004388 -0.047513 0 -0 0</pose>
        <mass>0.0185279</mass>
        <inertia>
          <ixx>2.69352e-05</ixx>
          <ixy>-1.47429e-09</ixy>
          <ixz>-5.82501e-08</ixz>
          <iyy>2.71324e-05</iyy>
          <iyz>1.19137e-06</iyz>
          <izz>6.50898e-07</izz>
        </inertia>
      </inertial>
      <collision name='RL_lower_leg_collision'>
        <pose frame=''>0 0 0 0 -0 0</pose>
        <geometry>
          <mesh>
            <scale>1 1 1</scale>
            <uri>model://pupperv2_description/meshes/RL_lower_leg.STL</uri>
          </mesh>
        </geometry>
      </collision>
      <collision name='RL_lower_leg_fixed_joint_lump__RL_toe_collision_1'>
        <pose frame=''>0 0.008325 -0.11 0 -0 0</pose>
        <geometry>
          <mesh>
            <scale>1 1 1</scale>
            <uri>model://pupperv2_description/meshes/RL_toe.STL</uri>
          </mesh>
        </geometry>
        <surface>
          <contact>
            <ode>
              <kp>1e+06</kp>
              <kd>1</kd>
              <max_vel>0</max_vel>
              <min_depth>0.001</min_depth>
            </ode>
          </contact>
          <friction>
            <ode>
              <mu>0.8</mu>
              <mu2>0.8</mu2>
            </ode>
          </friction>
        </surface>
      </collision>
      <visual name='RL_lower_leg_visual'>
        <pose frame=''>0 0 0 0 -0 0</pose>
        <geometry>
          <mesh>
            <scale>1 1 1</scale>
            <uri>model://pupperv2_description/meshes/RL_lower_leg.STL</uri>
          </mesh>
        </geometry>
      </visual>
      <visual name='RL_lower_leg_fixed_joint_lump__RL_toe_visual_1'>
        <pose frame=''>0 0.008325 -0.11 0 -0 0</pose>
        <geometry>
          <mesh>
            <scale>1 1 1</scale>
            <uri>model://pupperv2_description/meshes/RL_toe.STL</uri>
          </mesh>
        </geometry>
        <material>
          <script>
            <uri>__default__</uri>
            <name>__default__</name>
          </script>
        </material>
      </visual>
      <gravity>1</gravity>
      <velocity_decay/>
    </link>
    <joint name='RL_upper_leg_RL_lower_leg' type='revolute'>
      <child>RL_lower_leg</child>
      <parent>RL_upper_leg</parent>
      <axis>
        <xyz>0 1 0</xyz>
        <limit>
          <lower>-2.8798</lower>
          <upper>2.8798</upper>
          <effort>100</effort>
          <velocity>2.5</velocity>
        </limit>
        <dynamics>
          <spring_reference>0</spring_reference>
          <spring_stiffness>0</spring_stiffness>
        </dynamics>
        <use_parent_model_frame>1</use_parent_model_frame>
      </axis>
    </joint>
    <link name='RR_hip'>
      <pose frame=''>-0.12284 -0.0474 0.00461 0 -0 0</pose>
      <inertial>
        <pose frame=''>-0.022479 -0.003274 0.000397 0 -0 0</pose>
        <mass>0.032069</mass>
        <inertia>
          <ixx>5.9912e-06</ixx>
          <ixy>-4.4714e-07</ixy>
          <ixz>1.8534e-10</ixz>
          <iyy>2.954e-06</iyy>
          <iyz>-6.2909e-08</iyz>
          <izz>5.7295e-06</izz>
        </inertia>
      </inertial>
      <collision name='RR_hip_collision'>
        <pose frame=''>0 0 0 0 -0 0</pose>
        <geometry>
          <mesh>
            <scale>1 1 1</scale>
            <uri>model://pupperv2_description/meshes/RR_hip.STL</uri>
          </mesh>
        </geometry>
      </collision>
      <visual name='RR_hip_visual'>
        <pose frame=''>0 0 0 0 -0 0</pose>
        <geometry>
          <mesh>
            <scale>1 1 1</scale>
            <uri>model://pupperv2_description/meshes/RR_hip.STL</uri>
          </mesh>
        </geometry>
      </visual>
    </link>
    <joint name='base_link_RR_hip' type='revolute'>
      <child>RR_hip</child>
      <parent>base_link</parent>
      <axis>
        <xyz>1 0 0</xyz>
        <limit>
          <lower>-0.7854</lower>
          <upper>0.7854</upper>
          <effort>100</effort>
          <velocity>2.5</velocity>
        </limit>
        <dynamics>
          <spring_reference>0</spring_reference>
          <spring_stiffness>0</spring_stiffness>
        </dynamics>
        <use_parent_model_frame>1</use_parent_model_frame>
      </axis>
    </joint>
    <link name='RR_upper_leg'>
      <pose frame=''>-0.148865 -0.07275 0.00461 0 -0 0</pose>
      <inertial>
        <pose frame=''>-0.000116 -0.025203 -0.048064 0 -0 0</pose>
        <mass>0.054665</mass>
        <inertia>
          <ixx>2.4386e-05</ixx>
          <ixy>1.682e-10</ixy>
          <ixz>-2.6061e-07</ixz>
          <iyy>2.3437e-05</iyy>
          <iyz>-2.7137e-07</iyz>
          <izz>6.6679e-06</izz>
        </inertia>
      </inertial>
      <collision name='RR_upper_leg_collision'>
        <pose frame=''>0 0 0 0 -0 0</pose>
        <geometry>
          <mesh>
            <scale>1 1 1</scale>
            <uri>model://pupperv2_description/meshes/RR_upper_leg.STL</uri>
          </mesh>
        </geometry>
      </collision>
      <visual name='RR_upper_leg_visual'>
        <pose frame=''>0 0 0 0 -0 0</pose>
        <geometry>
          <mesh>
            <scale>1 1 1</scale>
            <uri>model://pupperv2_description/meshes/RR_upper_leg.STL</uri>
          </mesh>
        </geometry>
      </visual>
    </link>
    <joint name='RR_hip_RR_upper_leg' type='revolute'>
      <child>RR_upper_leg</child>
      <parent>RR_hip</parent>
      <axis>
        <xyz>0 1 0</xyz>
        <limit>
          <lower>-4.4506</lower>
          <upper>1.309</upper>
          <effort>100</effort>
          <velocity>2.5</velocity>
        </limit>
        <dynamics>
          <spring_reference>0</spring_reference>
          <spring_stiffness>0</spring_stiffness>
        </dynamics>
        <use_parent_model_frame>1</use_parent_model_frame>
      </axis>
    </joint>
    <link name='RR_lower_leg'>
      <pose frame=''>-0.148865 -0.07275 -0.07539 0 -0 0</pose>
      <inertial>
        <pose frame=''>3.2e-05 -0.004401 -0.047451 0 -0 0</pose>
        <mass>0.0185509</mass>
        <inertia>
          <ixx>2.6944e-05</ixx>
          <ixy>1.53789e-09</ixy>
          <ixz>-5.9142e-08</ixz>
          <iyy>2.71415e-05</iyy>
          <iyz>-1.19065e-06</iyz>
          <izz>6.51218e-07</izz>
        </inertia>
      </inertial>
      <collision name='RR_lower_leg_collision'>
        <pose frame=''>0 0 0 0 -0 0</pose>
        <geometry>
          <mesh>
            <scale>1 1 1</scale>
            <uri>model://pupperv2_description/meshes/RR_lower_leg.STL</uri>
          </mesh>
        </geometry>
      </collision>
      <collision name='RR_lower_leg_fixed_joint_lump__RR_toe_collision_1'>
        <pose frame=''>0 -0.008325 -0.11 0 -0 0</pose>
        <geometry>
          <mesh>
            <scale>1 1 1</scale>
            <uri>model://pupperv2_description/meshes/RR_toe.STL</uri>
          </mesh>
        </geometry>
        <surface>
          <contact>
            <ode>
              <kp>1e+06</kp>
              <kd>1</kd>
              <max_vel>0</max_vel>
              <min_depth>0.001</min_depth>
            </ode>
          </contact>
          <friction>
            <ode>
              <mu>0.8</mu>
              <mu2>0.8</mu2>
            </ode>
          </friction>
        </surface>
      </collision>
      <visual name='RR_lower_leg_visual'>
        <pose frame=''>0 0 0 0 -0 0</pose>
        <geometry>
          <mesh>
            <scale>1 1 1</scale>
            <uri>model://pupperv2_description/meshes/RR_lower_leg.STL</uri>
          </mesh>
        </geometry>
      </visual>
      <visual name='RR_lower_leg_fixed_joint_lump__RR_toe_visual_1'>
        <pose frame=''>0 -0.008325 -0.11 0 -0 0</pose>
        <geometry>
          <mesh>
            <scale>1 1 1</scale>
            <uri>model://pupperv2_description/meshes/RR_toe.STL</uri>
          </mesh>
        </geometry>
        <material>
          <script>
            <uri>__default__</uri>
            <name>__default__</name>
          </script>
        </material>
      </visual>
      <gravity>1</gravity>
      <velocity_decay/>
    </link>
    <joint name='RR_upper_leg_RR_lower_leg' type='revolute'>
      <child>RR_lower_leg</child>
      <parent>RR_upper_leg</parent>
      <axis>
        <xyz>0 1 0</xyz>
        <limit>
          <lower>-2.8798</lower>
          <upper>2.8798</upper>
          <effort>100</effort>
          <velocity>2.5</velocity>
        </limit>
        <dynamics>
          <spring_reference>0</spring_reference>
          <spring_stiffness>0</spring_stiffness>
        </dynamics>
        <use_parent_model_frame>1</use_parent_model_frame>
      </axis>
    </joint>
    <plugin name='gazebo_ros_control' filename='libgazebo_ros_control.so'>
      <legacyModeNS>1</legacyModeNS>
      <robotSimType>gazebo_ros_control/DefaultRobotHWSim</robotSimType>
    </plugin>
    <plugin name='imu_controller' filename='libhector_gazebo_ros_imu.so'>
      <updateRate>50.0</updateRate>
      <topicName>imu/data</topicName>
      <accelDrift>0.005 0.005 0.005</accelDrift>
      <accelGaussianNoise>0.005 0.005 0.005</accelGaussianNoise>
      <rateDrift>0.005 0.005 0.005</rateDrift>
      <rateGaussianNoise>0.005 0.005 0.005</rateGaussianNoise>
      <headingDrift>0.005</headingDrift>
      <headingGaussianNoise>0.005</headingGaussianNoise>
      <bodyName>base_link</bodyName>
      <xyzOffset>0 0 0</xyzOffset>
      <rpyOffset>0 -0 0</rpyOffset>
    </plugin>
    <static>0</static>
    <plugin name='p3d_base_controller' filename='libgazebo_ros_p3d.so'>
      <alwaysOn>1</alwaysOn>
      <updateRate>10.0</updateRate>
      <bodyName>base_link</bodyName>
      <topicName>odom/ground_truth</topicName>
      <gaussianNoise>0.01</gaussianNoise>
      <frameName>world</frameName>
      <xyzOffsets>0 0 0</xyzOffsets>
      <rpyOffsets>0 0 0</rpyOffsets>
    </plugin>
  </model>
</sdf>
